Workbook

Sheet Mexico
A1: Población total | B1: 2010 | G1: Población total | H1: 2020 | N1: Población total | O1: Interpolación 2019
A2: Lugar de nacimiento : Total
A4: Consulta de: Población total con estimación Por: Edad Según: Sexo | G4: Consulta de: Población total Por: Edad Según: Sexo
B6: Total | C6: Hombre | D6: Mujer | H6: Total | I6: Hombres | J6: Mujeres | N6: Total | O6: Hombres | P6: Mujeres
A7: Total | B7: 112,336,538 | C7: 54,855,231 | D7: 57,481,307 | G7: Total | H7: 126,014,024 | I7: 61,473,390 | J7: 64,540,634 | M7: Total | N7: =B7 * EXP((LN(H7/B7)/10) * 9) -> 1.2457448e+08 | O7: =C7 * EXP((LN(I7/C7)/10) * 9) -> 60777139 | P7: =D7 * EXP((LN(J7/D7)/10) * 9) -> 63797340
A8: De 0 a 4 años | B8: 10,528,322 | C8: 5,346,943 | D8: 5,181,379 | G8: De 0 a 4 años | H8: 10,047,365 | I8: 5,077,482 | J8: 4,969,883 | M8: De 0 a 4 años | N8: =B8 * EXP((LN(H8/B8)/10) * 9) -> 10094455 | O8: =C8 * EXP((LN(I8/C8)/10) * 9) -> 5103805.4 | P8: =D8 * EXP((LN(J8/D8)/10) * 9) -> 4990638.2
A9: De 5 a 9 años | B9: 11,047,537 | C9: 5,604,175 | D9: 5,443,362 | G9: De 5 a 9 años | H9: 10,764,379 | I9: 5,453,091 | J9: 5,311,288 | M9: De 5 a 9 años | N9: =B9 * EXP((LN(H9/B9)/10) * 9) -> 10792365 | O9: =C9 * EXP((LN(I9/C9)/10) * 9) -> 5468014.3 | P9: =D9 * EXP((LN(J9/D9)/10) * 9) -> 5324349.9
A10: De 10 a 14 años | B10: 10,939,937 | C10: 5,547,613 | D10: 5,392,324 | G10: De 10 a 14 años | H10: 10,943,540 | I10: 5,554,260 | J10: 5,389,280 | M10: De 10 a 14 años | N10: =B10 * EXP((LN(H10/B10)/10) * 9) -> 10943180 | O10: =C10 * EXP((LN(I10/C10)/10) * 9) -> 5553594.9 | P10: =D10 * EXP((LN(J10/D10)/10) * 9) -> 5389584.3
A11: De 15 a 19 años | B11: 11,026,112 | C11: 5,520,121 | D11: 5,505,991 | G11: De 15 a 19 años | H11: 10,806,690 | I11: 5,462,150 | J11: 5,344,540 | M11: De 15 a 19 años | N11: =B11 * EXP((LN(H11/B11)/10) * 9) -> 10828434 | O11: =C11 * EXP((LN(I11/C11)/10) * 9) -> 5467919.6 | P11: =D11 * EXP((LN(J11/D11)/10) * 9) -> 5360469.7
A12: De 20 a 24 años | B12: 9,892,271 | C12: 4,813,204 | D12: 5,079,067 | G12: De 20 a 24 años | H12: 10,422,095 | I12: 5,165,884 | J12: 5,256,211 | M12: De 20 a 24 años | N12: =B12 * EXP((LN(H12/B12)/10) * 9) -> 10367860 | O12: =C12 * EXP((LN(I12/C12)/10) * 9) -> 5129483.2 | P12: =D12 * EXP((LN(J12/D12)/10) * 9) -> 5238222.1
A13: De 25 a 29 años | B13: 8,788,177 | C13: 4,205,975 | D13: 4,582,202 | G13: De 25 a 29 años | H13: 9,993,001 | I13: 4,861,404 | J13: 5,131,597 | M13: De 25 a 29 años | N13: =B13 * EXP((LN(H13/B13)/10) * 9) -> 9865434.5 | O13: =C13 * EXP((LN(I13/C13)/10) * 9) -> 4791507.9 | P13: =D13 * EXP((LN(J13/D13)/10) * 9) -> 5073816
A14: De 30 a 34 años | B14: 8,470,798 | C14: 4,026,031 | D14: 4,444,767 | G14: De 30 a 34 años | H14: 9,420,827 | I14: 4,527,726 | J14: 4,893,101 | M14: De 30 a 34 años | N14: =B14 * EXP((LN(H14/B14)/10) * 9) -> 9321215.7 | O14: =C14 * EXP((LN(I14/C14)/10) * 9) -> 4474863.9 | P14: =D14 * EXP((LN(J14/D14)/10) * 9) -> 4846304.1
A15: De 35 a 39 años | B15: 8,292,987 | C15: 3,964,738 | D15: 4,328,249 | G15: De 35 a 39 años | H15: 9,020,276 | I15: 4,331,530 | J15: 4,688,746 | M15: De 35 a 39 años | N15: =B15 * EXP((LN(H15/B15)/10) * 9) -> 8944765.1 | O15: =C15 * EXP((LN(I15/C15)/10) * 9) -> 4293373.2 | P15: =D15 * EXP((LN(J15/D15)/10) * 9) -> 4651384.7
A16: De 40 a 44 años | B16: 7,009,226 | C16: 3,350,322 | D16: 3,658,904 | G16: De 40 a 44 años | H16: 8,503,586 | I16: 4,062,304 | J16: 4,441,282 | M16: De 40 a 44 años | N16: =B16 * EXP((LN(H16/B16)/10) * 9) -> 8340823 | O16: =C16 * EXP((LN(I16/C16)/10) * 9) -> 3984775.3 | P16: =D16 * EXP((LN(J16/D16)/10) * 9) -> 4356047.6
A17: De 45 a 49 años | B17: 5,928,730 | C17: 2,824,364 | D17: 3,104,366 | G17: De 45 a 49 años | H17: 7,942,413 | I17: 3,812,344 | J17: 4,130,069 | M17: De 45 a 49 años | N17: =B17 * EXP((LN(H17/B17)/10) * 9) -> 7713533.8 | O17: =C17 * EXP((LN(I17/C17)/10) * 9) -> 3699686.6 | P17: =D17 * EXP((LN(J17/D17)/10) * 9) -> 4013829
A18: De 50 a 54 años | B18: 5,064,291 | C18: 2,402,451 | D18: 2,661,840 | G18: De 50 a 54 años | H18: 7,037,532 | I18: 3,332,163 | J18: 3,705,369 | M18: De 50 a 54 años | N18: =B18 * EXP((LN(H18/B18)/10) * 9) -> 6809735 | O18: =C18 * EXP((LN(I18/C18)/10) * 9) -> 3224920.9 | P18: =D18 * EXP((LN(J18/D18)/10) * 9) -> 3584813.1
... A26: No especificado | B26: 1,397,406 | C26: 700,219 | D26: 697,187 | G26: No especificado | H26: 273,386 | I26: 136,194 | J26: 137,192 | M26: No especificado | N26: =B26 * EXP((LN(H26/B26)/10) * 9) -> 321833.24 | O26: =C26 * EXP((LN(I26/C26)/10) * 9) -> 160422.61 | P26: =D26 * EXP((LN(J26/D26)/10) * 9) -> 161410.15
A30: FUENTE: INEGI. Censo de Población y Vivienda 2010. | G30: FUENTE: INEGI. Censo de Población y Vivienda 2020. Cuestionario Básico.
C34: Tasas de crecimiento para el total de la población | M34: Tasas de crecimiento exponencial para Edades Específicas MEF
M35: 15-19
A36: Fechas | B36: ti | C36: N | D36: r | F36: ti | G36: Δt | H36: N30/06/2019 | M36: Fechas | N36: ti | O36: N | P36: r | R36: ti | S36: Δt | T36: N30/06/2019
A37: 40186 | B37: =2010 + 7/12 + 1/365 -> 2010.5861 | C37: =B7 -> 112,336,538 | D37: =LN(C38/C37)/B39 -> 0.011385427 | F37: =2019+6/12+0/365 -> 2019.5 | G37: =F37-B37 -> 8.9139269 | H37: =C37*EXP(D38*G38) -> 112336538 | M37: 40186 | N37: =2010 + 7/12 + 1/365 -> 2010.5861 | O37: =D11 -> 5,505,991 | P37: =LN(O38/O37)/N39 -> -0.002949196 | R37: =2019+6/12+0/365 -> 2019.5 | S37: =R37-N37 -> 8.9139269 | T37: =O37*EXP(P37*S37) -> 5363130.5
A38: 43708 | B38: =2019 + 7/12 + 31/365 -> 2019.6683 | C38: =N7 -> 1.2457448e+08 | M38: 43708 | N38: =2019 + 7/12 + 31/365 -> 2019.6683 | O38: =P11 -> 5360469.7
A39: Δt | B39: =B38-B37 -> 9.0821918 | M39: Δt | N39: =N38-N37 -> 9.0821918
M41: 20-24
M42: Fechas | N42: ti | O42: N | P42: r | R42: ti | S42: Δt | T42: N30/06/2019
M43: 40186 | N43: =2010 + 7/12 + 1/365 -> 2010.5861 | O43: =D12 -> 5,079,067 | P43: =LN(O44/O43)/N45 -> 0.003397259 | R43: =2019+6/12+0/365 -> 2019.5 | S43: =R43-N43 -> 8.9139269 | T43: =O43*EXP(P43*S43) -> 5235228.6
M44: 43708 | N44: =2019 + 7/12 + 31/365 -> 2019.6683 | O44: =P12 -> 5238222.1
M45: Δt | N45: =N44-N43 -> 9.0821918
M47: 25-29
M48: Fechas | N48: ti | O48: N | P48: r | R48: ti | S48: Δt | T48: N30/06/2019
M49: 40186 | N49: =2010 + 7/12 + 1/365 -> 2010.5861 | O49: =D13 -> 4,582,202 | P49: =LN(O50/O49)/N51 -> 0.011221248 | R49: =2019+6/12+0/365 -> 2019.5 | S49: =R49-N49 -> 8.9139269 | T49: =O49*EXP(P49*S49) -> 5064244.9
M50: 43708 | N50: =2019 + 7/12 + 31/365 -> 2019.6683 | O50: =P13 -> 5073816
M51: Δt | N51: =N50-N49 -> 9.0821918
M53: 30-34
M54: Fechas | N54: ti | O54: N | P54: r | R54: ti | S54: Δt | T54: N30/06/2019
M55: 40186 | N55: =2010 + 7/12 + 1/365 -> 2010.5861 | O55: =D14 -> 4,444,767 | P55: =LN(O56/O55)/N57 -> 0.0095229132 | R55: =2019+6/12+0/365 -> 2019.5 | S55: =R55-N55 -> 8.9139269 | T55: =O55*EXP(P55*S55) -> 4838544.7
M56: 43708 | N56: =2019 + 7/12 + 31/365 -> 2019.6683 | O56: =P14 -> 4846304.1
M57: Δt | N57: =N56-N55 -> 9.0821918
M59: 35-39
...

Sheet Veracruz
A1: Población total | G1: Población total
A2: Entidad y municipio : Veracruz de Ignacio de la Llave | G2: Entidad y municipio : Veracruz de Ignacio de la Llave
A4: Consulta de: Población total con estimación Por: Edad Según: Sexo | G4: Consulta de: Población total Por: Edad Según: Sexo
B6: Total | C6: Hombre | D6: Mujer | H6: Total | I6: Hombres | J6: Mujeres | N6: Total | O6: Hombres | P6: Mujeres
A7: Total | B7: 7,643,194 | C7: 3,695,679 | D7: 3,947,515 | G7: Total | H7: 8,062,579 | I7: 3,871,774 | J7: 4,190,805 | M7: Total | N7: =B7 * EXP((LN(H7/B7)/10) * 9) -> 8019625.2 | O7: =C7 * EXP((LN(I7/C7)/10) * 9) -> 3853793.4 | P7: =D7 * EXP((LN(J7/D7)/10) * 9) -> 4165816
A8: De 0 a 4 años | B8: 662,288 | C8: 335,899 | D8: 326,389 | G8: De 0 a 4 años | H8: 600,253 | I8: 303,113 | J8: 297,140 | M8: De 0 a 4 años | N8: =B8 * EXP((LN(H8/B8)/10) * 9) -> 606185.57 | O8: =C8 * EXP((LN(I8/C8)/10) * 9) -> 306242.16 | P8: =D8 * EXP((LN(J8/D8)/10) * 9) -> 299942.88
A9: De 5 a 9 años | B9: 728,767 | C9: 369,775 | D9: 358,992 | G9: De 5 a 9 años | H9: 675,182 | I9: 342,335 | J9: 332,847 | M9: De 5 a 9 años | N9: =B9 * EXP((LN(H9/B9)/10) * 9) -> 680358.23 | O9: =C9 * EXP((LN(I9/C9)/10) * 9) -> 344984.77 | P9: =D9 * EXP((LN(J9/D9)/10) * 9) -> 335373.44
A10: De 10 a 14 años | B10: 741,526 | C10: 376,924 | D10: 364,602 | G10: De 10 a 14 años | H10: 685,468 | I10: 347,680 | J10: 337,788 | M10: De 10 a 14 años | N10: =B10 * EXP((LN(H10/B10)/10) * 9) -> 690877.59 | O10: =C10 * EXP((LN(I10/C10)/10) * 9) -> 350499.27 | P10: =D10 * EXP((LN(J10/D10)/10) * 9) -> 340378.17
A11: De 15 a 19 años | B11: 759,388 | C11: 381,351 | D11: 378,037 | G11: De 15 a 19 años | H11: 681,548 | I11: 344,153 | J11: 337,395 | M11: De 15 a 19 años | N11: =B11 * EXP((LN(H11/B11)/10) * 9) -> 688958.68 | O11: =C11 * EXP((LN(I11/C11)/10) * 9) -> 347703.36 | P11: =D11 * EXP((LN(J11/D11)/10) * 9) -> 341254.36
A12: De 20 a 24 años | B12: 642,093 | C12: 307,562 | D12: 334,531 | G12: De 20 a 24 años | H12: 600,394 | I12: 292,359 | J12: 308,035 | M12: De 20 a 24 años | N12: =B12 * EXP((LN(H12/B12)/10) * 9) -> 604439.03 | O12: =C12 * EXP((LN(I12/C12)/10) * 9) -> 293844.85 | P12: =D12 * EXP((LN(J12/D12)/10) * 9) -> 310587.3
A13: De 25 a 29 años | B13: 557,762 | C13: 259,153 | D13: 298,609 | G13: De 25 a 29 años | H13: 580,421 | I13: 272,684 | J13: 307,737 | M13: De 25 a 29 años | N13: =B13 * EXP((LN(H13/B13)/10) * 9) -> 578114.28 | O13: =C13 * EXP((LN(I13/C13)/10) * 9) -> 271299.7 | P13: =D13 * EXP((LN(J13/D13)/10) * 9) -> 306811.78
A14: De 30 a 34 años | B14: 539,685 | C14: 247,094 | D14: 292,591 | G14: De 30 a 34 años | H14: 568,121 | I14: 263,409 | J14: 304,712 | M14: De 30 a 34 años | N14: =B14 * EXP((LN(H14/B14)/10) * 9) -> 565211.24 | O14: =C14 * EXP((LN(I14/C14)/10) * 9) -> 261730.16 | P14: =D14 * EXP((LN(J14/D14)/10) * 9) -> 303477.64
A15: De 35 a 39 años | B15: 542,754 | C15: 251,277 | D15: 291,477 | G15: De 35 a 39 años | H15: 558,791 | I15: 258,605 | J15: 300,186 | M15: De 35 a 39 años | N15: =B15 * EXP((LN(H15/B15)/10) * 9) -> 557166.2 | O15: =C15 * EXP((LN(I15/C15)/10) * 9) -> 257862.68 | P15: =D15 * EXP((LN(J15/D15)/10) * 9) -> 299303.52
A16: De 40 a 44 años | B16: 486,810 | C16: 228,657 | D16: 258,153 | G16: De 40 a 44 años | H16: 537,667 | I16: 247,288 | J16: 290,379 | M16: De 40 a 44 años | N16: =B16 * EXP((LN(H16/B16)/10) * 9) -> 532350.9 | O16: =C16 * EXP((LN(I16/C16)/10) * 9) -> 245358.55 | P16: =D16 * EXP((LN(J16/D16)/10) * 9) -> 286983.15
A17: De 45 a 49 años | B17: 424,845 | C17: 201,515 | D17: 223,330 | G17: De 45 a 49 años | H17: 516,152 | I17: 240,159 | J17: 275,993 | M17: De 45 a 49 años | N17: =B17 * EXP((LN(H17/B17)/10) * 9) -> 506200.89 | O17: =C17 * EXP((LN(I17/C17)/10) * 9) -> 235982.46 | P17: =D17 * EXP((LN(J17/D17)/10) * 9) -> 270210.96
A18: De 50 a 54 años | B18: 365,591 | C18: 172,802 | D18: 192,789 | G18: De 50 a 54 años | H18: 488,510 | I18: 227,672 | J18: 260,838 | M18: De 50 a 54 años | N18: =B18 * EXP((LN(H18/B18)/10) * 9) -> 474554.03 | O18: =C18 * EXP((LN(I18/C18)/10) * 9) -> 221479.5 | P18: =D18 * EXP((LN(J18/D18)/10) * 9) -> 253070.78
... A26: No especificado | B26: 94,957 | C26: 47,396 | D26: 47,561 | G26: No especificado | H26: 3,470 | I26: 1,707 | J26: 1,763 | M26: No especificado | N26: =B26 * EXP((LN(H26/B26)/10) * 9) -> 4831.1356 | O26: =C26 * EXP((LN(I26/C26)/10) * 9) -> 2380.0404 | P26: =D26 * EXP((LN(J26/D26)/10) * 9) -> 2451.05
A30: FUENTE: INEGI. Censo de Población y Vivienda 2010. | G30: FUENTE: INEGI. Censo de Población y Vivienda 2020. Cuestionario Básico.
C34: Tasas de crecimiento para el total de la población | M34: Tasas de crecimiento exponencial para Edades Específicas MEF
M35: 15-19
A36: Fechas | B36: ti | C36: N | D36: r | F36: ti | G36: Δt | H36: N30/06/2019 | M36: Fechas | N36: ti | O36: N | P36: r | R36: ti | S36: Δt | T36: N30/06/2019
A37: 40186 | B37: =2010 + 7/12 + 1/365 -> 2010.5861 | C37: =B7 -> 7,643,194 | D37: =LN(C38/C37)/B39 -> 0.0052934482 | F37: =2019+6/12+0/365 -> 2019.5 | G37: =F37-B37 -> 8.9139269 | H37: =C37*EXP(D38*G38) -> 7643194 | M37: 40186 | N37: =2010 + 7/12 + 1/365 -> 2010.5861 | O37: =D11 -> 378,037 | P37: =LN(O38/O37)/N39 -> -0.011270842 | R37: =2019+6/12+0/365 -> 2019.5 | S37: =R37-N37 -> 8.9139269 | T37: =O37*EXP(P37*S37) -> 341902.16
A38: 43708 | B38: =2019 + 7/12 + 31/365 -> 2019.6683 | C38: =N7 -> 8019625.2 | M38: 43708 | N38: =2019 + 7/12 + 31/365 -> 2019.6683 | O38: =P11 -> 341254.36
A39: Δt | B39: =B38-B37 -> 9.0821918 | M39: Δt | N39: =N38-N37 -> 9.0821918
M41: 20-24
M42: Fechas | N42: ti | O42: N | P42: r | R42: ti | S42: Δt | T42: N30/06/2019
M43: 40186 | N43: =2010 + 7/12 + 1/365 -> 2010.5861 | O43: =D12 -> 334,531 | P43: =LN(O44/O43)/N45 -> -0.0081769386 | R43: =2019+6/12+0/365 -> 2019.5 | S43: =R43-N43 -> 8.9139269 | T43: =O43*EXP(P43*S43) -> 311014.93
M44: 43708 | N44: =2019 + 7/12 + 31/365 -> 2019.6683 | O44: =P12 -> 310587.3
M45: Δt | N45: =N44-N43 -> 9.0821918
M47: 25-29
M48: Fechas | N48: ti | O48: N | P48: r | R48: ti | S48: Δt | T48: N30/06/2019
M49: 40186 | N49: =2010 + 7/12 + 1/365 -> 2010.5861 | O49: =D13 -> 298,609 | P49: =LN(O50/O49)/N51 -> 0.0029838004 | R49: =2019+6/12+0/365 -> 2019.5 | S49: =R49-N49 -> 8.9139269 | T49: =O49*EXP(P49*S49) -> 306657.78
M50: 43708 | N50: =2019 + 7/12 + 31/365 -> 2019.6683 | O50: =P13 -> 306811.78
M51: Δt | N51: =N50-N49 -> 9.0821918
M53: 30-34
M54: Fechas | N54: ti | O54: N | P54: r | R54: ti | S54: Δt | T54: N30/06/2019
M55: 40186 | N55: =2010 + 7/12 + 1/365 -> 2010.5861 | O55: =D14 -> 292,591 | P55: =LN(O56/O55)/N57 -> 0.0040223996 | R55: =2019+6/12+0/365 -> 2019.5 | S55: =R55-N55 -> 8.9139269 | T55: =O55*EXP(P55*S55) -> 303272.31
M56: 43708 | N56: =2019 + 7/12 + 31/365 -> 2019.6683 | O56: =P14 -> 303477.64
M57: Δt | N57: =N56-N55 -> 9.0821918
M59: 35-39
...

Sheet Nacimientos y tablas de vida,Me
B1: Nacimientos 2019 | G1: Mexico
G2: Nacimientos por sexo
G3: 2019
B4: Edad | C4: Mexico 2019 | D4: Población 30/06/2019
B5: Total | C5: =SUM(C6:C12) -> 1942234 | D5: =SUM(D6:D12) -> 33483096 | G5: Hombres | H5: Mujeres | I5: Total
B6: De 15 a 19 años | C6: 315681.16 | D6: =Mexico!T37 -> 5363130.5 | G6: 987870 | H6: 954364 | I6: =SUM(G6:H6) -> 1942234
B7: De 20 a 24 años | C7: 545329.57 | D7: =Mexico!T43 -> 5235228.6
B8: De 25 a 29 años | C8: 511967.39 | D8: =Mexico!T49 -> 5064244.9 | G8: K | H8: =H6/I6 -> 0.49137437
B9: De 30 a 34 años | C9: 347637.04 | D9: =Mexico!T55 -> 4838544.7
B10: De 35 a 39 años | C10: 174294.23 | D10: =Mexico!T61 -> 4645184
B11: De 40 a 44 años | C11: 43848.977 | D11: =Mexico!T67 -> 4341995.4
B12: De 45 a 49 años | C12: 3475.6292 | D12: =Mexico!T73 -> 3994767.7
B14: lt_desc | C14: year | D14: sex | E14: age | F14: mx | G14: qx | H14: ax | I14: lx | J14: dx | K14: Lx | L14: Tx | M14: ex | O14: lt_desc | P14: year | Q14: sex | R14: age | S14: mx | T14: qx | U14: ax | V14: lx | W14: dx | X14: Lx | Y14: Tx | Z14: ex
B15: LT VR/Census, MEX | C15: 2019 | D15: m | E15: 0 | F15: 0.014127 | G15: 0.013946 | H15: 0.08 | I15: 100000 | J15: 1395 | K15: 98721 | L15: 7303478 | M15: 73.03 | O15: LT VR/Census, MEX | P15: 2019 | Q15: f | R15: 0 | S15: 0.011322 | T15: 0.011206 | U15: 0.08 | V15: 100000 | W15: 1121 | X15: 98974 | Y15: 7937292 | Z15: 79.37
B16: LT VR/Census, MEX | C16: 2019 | D16: m | E16: 1 | F16: 0.000602 | G16: 0.002404 | H16: 1.61 | I16: 98605 | J16: 237 | K16: 393855 | L16: 7204757 | M16: 73.07 | O16: LT VR/Census, MEX | P16: 2019 | Q16: f | R16: 1 | S16: 0.000524 | T16: 0.002094 | U16: 1.5 | V16: 98879 | W16: 207 | X16: 395001 | Y16: 7838317 | Z16: 79.27
B17: LT VR/Census, MEX | C17: 2019 | D17: m | E17: 5 | F17: 0.000247 | G17: 0.001234 | H17: 2.5 | I17: 98368 | J17: 121 | K17: 491538 | L17: 6810902 | M17: 69.24 | O17: LT VR/Census, MEX | P17: 2019 | Q17: f | R17: 5 | S17: 0.000213 | T17: 0.001064 | U17: 2.5 | V17: 98672 | W17: 105 | X17: 493099 | Y17: 7443317 | Z17: 75.43
B18: LT VR/Census, MEX | C18: 2019 | D18: m | E18: 10 | F18: 0.000337 | G18: 0.001685 | H18: 2.5 | I18: 98247 | J18: 166 | K18: 490821 | L18: 6319364 | M18: 64.32 | O18: LT VR/Census, MEX | P18: 2019 | Q18: f | R18: 10 | S18: 0.000242 | T18: 0.00121 | U18: 2.5 | V18: 98567 | W18: 119 | X18: 492538 | Y18: 6950217 | Z18: 70.51
B19: LT VR/Census, MEX | C19: 2019 | D19: m | E19: 15 | F19: 0.001232 | G19: 0.006142 | H19: 2.5 | I19: 98081 | J19: 602 | K19: 488901 | L19: 5828543 | M19: 59.43 | O19: LT VR/Census, MEX | P19: 2019 | Q19: f | R19: 15 | S19: 0.000464 | T19: 0.002316 | U19: 2.5 | V19: 98448 | W19: 228 | X19: 491670 | Y19: 6457679 | Z19: 65.59
B20: LT VR/Census, MEX | C20: 2019 | D20: m | E20: 20 | F20: 0.002316 | G20: 0.011511 | H20: 2.5 | I20: 97479 | J20: 1122 | K20: 484590 | L20: 5339643 | M20: 54.78 | O20: LT VR/Census, MEX | P20: 2019 | Q20: f | R20: 20 | S20: 0.000607 | T20: 0.003031 | U20: 2.5 | V20: 98220 | W20: 298 | X20: 490356 | Y20: 5966009 | Z20: 60.74
B21: LT VR/Census, MEX | C21: 2019 | D21: m | E21: 25 | F21: 0.002909 | G21: 0.01444 | H21: 2.5 | I21: 96357 | J21: 1391 | K21: 478306 | L21: 4855053 | M21: 50.39 | O21: LT VR/Census, MEX | P21: 2019 | Q21: f | R21: 25 | S21: 0.000739 | T21: 0.003687 | U21: 2.5 | V21: 97922 | W21: 361 | X21: 488709 | Y21: 5475653 | Z21: 55.92
B22: LT VR/Census, MEX | C22: 2019 | D22: m | E22: 30 | F22: 0.003122 | G22: 0.01549 | H22: 2.5 | I22: 94965 | J22: 1471 | K22: 471150 | L22: 4376747 | M22: 46.09 | O22: LT VR/Census, MEX | P22: 2019 | Q22: f | R22: 30 | S22: 0.00089 | T22: 0.004438 | U22: 2.5 | V22: 97561 | W22: 433 | X22: 486724 | Y22: 4986945 | Z22: 51.12
B23: LT VR/Census, MEX | C23: 2019 | D23: m | E23: 35 | F23: 0.003563 | G23: 0.01766 | H23: 2.5 | I23: 93494 | J23: 1651 | K23: 463344 | L23: 3905598 | M23: 41.77 | O23: LT VR/Census, MEX | P23: 2019 | Q23: f | R23: 35 | S23: 0.001187 | T23: 0.005917 | U23: 2.5 | V23: 97128 | W23: 575 | X23: 484204 | Y23: 4500221 | Z23: 46.33
B24: LT VR/Census, MEX | C24: 2019 | D24: m | E24: 40 | F24: 0.004481 | G24: 0.022155 | H24: 2.5 | I24: 91843 | J24: 2035 | K24: 454130 | L24: 3442253 | M24: 37.48 | O24: LT VR/Census, MEX | P24: 2019 | Q24: f | R24: 40 | S24: 0.001766 | T24: 0.008789 | U24: 2.5 | V24: 96554 | W24: 849 | X24: 480646 | Y24: 4016017 | Z24: 41.59
B25: LT VR/Census, MEX | C25: 2019 | D25: m | E25: 45 | F25: 0.005676 | G25: 0.027981 | H25: 2.5 | I25: 89809 | J25: 2513 | K25: 442760 | L25: 2988124 | M25: 33.27 | O25: LT VR/Census, MEX | P25: 2019 | Q25: f | R25: 45 | S25: 0.002717 | T25: 0.013494 | U25: 2.5 | V25: 95705 | W25: 1291 | X25: 475296 | Y25: 3535371 | Z25: 36.94
B26: LT VR/Census, MEX | C26: 2019 | D26: m | E26: 50 | F26: 0.007547 | G26: 0.037038 | H26: 2.5 | I26: 87296 | J26: 3233 | K26: 428395 | L26: 2545363 | M26: 29.16 | O26: LT VR/Census, MEX | P26: 2019 | Q26: f | R26: 50 | S26: 0.004073 | T26: 0.020159 | U26: 2.5 | V26: 94413 | W26: 1903 | X26: 467309 | Y26: 3060075 | Z26: 32.41
... B32: LT VR/Census, MEX | C32: 2019 | D32: m | E32: 80 | F32: 0.074361 | G32: 0.313522 | H32: 2.5 | I32: 44829 | J32: 14055 | K32: 189007 | L32: 414415 | M32: 9.24 | O32: LT VR/Census, MEX | P32: 2019 | Q32: f | R32: 80 | S32: 0.060602 | T32: 0.263143 | U32: 2.5 | V32: 58768 | W32: 15464 | X32: 255180 | Y32: 592884 | Z32: 10.09
B33: LT VR/Census, MEX | C33: 2019 | D33: m | E33: 85 | F33: 0.136525 | G33: 1 | H33: NA | I33: 30774 | J33: 30774 | K33: 225408 | L33: 225408 | M33: 7.32 | O33: LT VR/Census, MEX | P33: 2019 | Q33: f | R33: 85 | S33: 0.12823 | T33: 1 | U33: NA | V33: 43304 | W33: 43304 | X33: 337704 | Y33: 337704 | Z33: 7.8

Sheet Nacimientos y tablas de vida, V
B1: Nacimientos 2019 | G1: Veracruz
G2: Nacimientos por sexo
G3: 2019
B4: Edad | C4: Veracruz 2019 | D4: Población 30/06/2019
B5: Total | C5: =SUM(C6:C12) -> 109107 | D5: =SUM(D6:D12) -> 2117683.3 | G5: Hombres | H5: Mujeres | I5: Total
B6: De 15 a 19 años | C6: 19130.02 | D6: =Veracruz!T37 -> 341902.16 | G6: 55203 | H6: 53904 | I6: 109107
B7: De 20 a 24 años | C7: 30279.299 | D7: =Veracruz!T43 -> 311014.93
B8: De 25 a 29 años | C8: 28573.709 | D8: =Veracruz!T49 -> 306657.78 | G8: K | H8: =H6/I6 -> 0.49404713
B9: De 30 a 34 años | C9: 19118.852 | D9: =Veracruz!T55 -> 303272.31
B10: De 35 a 39 años | C10: 9508.6644 | D10: =Veracruz!T61 -> 299156.62
B11: De 40 a 44 años | C11: 2342.1406 | D11: =Veracruz!T67 -> 286420.8
B12: De 45 a 49 años | C12: 154.31529 | D12: =Veracruz!T73 -> 269258.71
B16: Tabla reducida de mortalidad, mujeres, Veracruz, 2019 | P16: Tabla reducida de mortalidad, hombres, Veracruz, 2019
B18: x | C18: n | D18: mx | E18: ax | F18: qx | G18: px | H18: lx | I18: dx | J18: Lx | K18: Tx | L18: ex | P18: x | Q18: n | R18: mx | S18: ax | T18: qx | U18: px | V18: lx | W18: dx | X18: Lx | Y18: Tx | Z18: ex
B19: 0 | C19: 1 | D19: 0.011783679 | E19: 0.085994301 | F19: 0.011658117 | G19: 0.98834188 | H19: 100000 | I19: 1165.8117 | J19: 98934.441 | K19: 7839635 | L19: 78.39635 | P19: 0 | Q19: 1 | R19: 0.013144409 | S19: 0.080279593 | T19: 0.012987402 | U19: 0.9870126 | V19: 100000 | W19: 1298.7402 | X19: 98805.522 | Y19: 7262802 | Z19: 72.62802
B20: 1 | C20: 4 | D20: 0.00055106764 | E20: 2 | F20: 0.0022018438 | G20: 0.99779816 | H20: 98834.188 | I20: 217.61745 | J20: 394901.52 | K20: 7740700.6 | L20: 78.320071 | P20: 1 | Q20: 4 | R20: 0.00060758441 | S20: 2 | T20: 0.002427388 | U20: 0.99757261 | V20: 98701.26 | W20: 239.58625 | X20: 394325.87 | Y20: 7163996.5 | Z20: 72.582625
B21: 5 | C21: 5 | D21: 0.00025663751 | E21: 2.5 | F21: 0.0012823648 | G21: 0.99871764 | H21: 98616.571 | I21: 126.46242 | J21: 492766.7 | K21: 7345799.1 | L21: 74.488486 | P21: 5 | Q21: 5 | R21: 0.00030749772 | S21: 2.5 | T21: 0.0015363076 | U21: 0.99846369 | V21: 98461.674 | W21: 151.26742 | X21: 491930.2 | Y21: 6769670.6 | Z21: 68.754373
B22: 10 | C22: 5 | D22: 0.00024698909 | E22: 2.5 | F22: 0.0012341834 | G22: 0.99876582 | H22: 98490.108 | I22: 121.55485 | J22: 492146.66 | K22: 6853032.4 | L22: 69.58092 | P22: 10 | Q22: 5 | R22: 0.00034837932 | S22: 2.5 | T22: 0.0017403808 | U22: 0.99825962 | V22: 98310.406 | W22: 171.09755 | X22: 491124.29 | Y22: 6277740.4 | Z22: 63.856317
B23: 15 | C23: 5 | D23: 0.00042275602 | E23: 2.5 | F23: 0.0021115484 | G23: 0.99788845 | H23: 98368.554 | I23: 207.70996 | J23: 491323.49 | K23: 6360885.7 | L23: 64.663813 | P23: 15 | Q23: 5 | R23: 0.0010253722 | S23: 2.5 | T23: 0.0051137523 | U23: 0.99488625 | V23: 98139.309 | W23: 501.86011 | X23: 489441.89 | Y23: 5786616.1 | Z23: 58.963286
B24: 20 | C24: 5 | D24: 0.00056401034 | E24: 2.5 | F24: 0.0028160809 | G24: 0.99718392 | H24: 98160.844 | I24: 276.42888 | J24: 490113.15 | K24: 5869562.2 | L24: 59.795352 | P24: 20 | Q24: 5 | R24: 0.0021781228 | S24: 2.5 | T24: 0.010831632 | U24: 0.98916837 | V24: 97637.449 | W24: 1057.573 | X24: 485543.31 | Y24: 5297174.3 | Z24: 54.25351
B25: 25 | C25: 5 | D25: 0.000777347 | E25: 2.5 | F25: 0.0038791963 | G25: 0.9961208 | H25: 97884.415 | I25: 379.71286 | J25: 488472.79 | K25: 5379449.1 | L25: 54.957156 | P25: 25 | Q25: 5 | R25: 0.0030619934 | S25: 2.5 | T25: 0.01519366 | U25: 0.98480634 | V25: 96579.876 | W25: 1467.4018 | X25: 479230.87 | Y25: 4811630.9 | Z25: 49.820223
B26: 30 | C26: 5 | D26: 0.001022347 | E26: 2.5 | F26: 0.0050987034 | G26: 0.9949013 | H26: 97504.702 | I26: 497.14755 | J26: 486280.64 | K26: 4890976.3 | L26: 50.16144 | P26: 30 | Q26: 5 | R26: 0.0031766225 | S26: 2.5 | T26: 0.01575797 | U26: 0.98424203 | V26: 95112.474 | W26: 1498.7795 | X26: 471815.42 | Y26: 4332400.1 | Z26: 45.550283
B27: 35 | C27: 5 | D27: 0.0012469743 | E27: 2.5 | F27: 0.0062154949 | G27: 0.99378451 | H27: 97007.554 | I27: 602.94996 | J27: 483530.4 | K27: 4404695.7 | L27: 45.405697 | P27: 35 | Q27: 5 | R27: 0.0035756577 | S27: 2.5 | T27: 0.017719888 | U27: 0.98228011 | V27: 93613.694 | W27: 1658.8241 | X27: 463921.41 | Y27: 3860584.7 | Z27: 41.239529
B28: 40 | C28: 5 | D28: 0.0019078806 | E28: 2.5 | F28: 0.0094941188 | G28: 0.99050588 | H28: 96404.604 | I28: 915.27677 | J28: 479734.83 | K28: 3921165.3 | L28: 40.674045 | P28: 40 | Q28: 5 | R28: 0.0043741725 | S28: 2.5 | T28: 0.021634282 | U28: 0.97836572 | V28: 91954.87 | W28: 1989.3776 | X28: 454800.91 | Y28: 3396663.2 | Z28: 36.938372
B29: 45 | C29: 5 | D29: 0.0031969779 | E29: 2.5 | F29: 0.015858144 | G29: 0.98414186 | H29: 95489.328 | I29: 1514.2835 | J29: 473660.93 | K29: 3441430.4 | L29: 36.039948 | P29: 45 | Q29: 5 | R29: 0.0059846194 | S29: 2.5 | T29: 0.029482001 | U29: 0.970518 | V29: 89965.493 | W29: 2652.3627 | X29: 443196.56 | Y29: 2941862.3 | Z29: 32.699897
B30: 50 | C30: 5 | D30: 0.004359993 | E30: 2.5 | F30: 0.021564908 | G30: 0.97843509 | H30: 93975.044 | I30: 2026.5631 | J30: 464808.81 | K30: 2967769.5 | L30: 31.5804 | P30: 50 | Q30: 5 | R30: 0.0080997387 | S30: 2.5 | T30: 0.039694898 | U30: 0.9603051 | V30: 87313.13 | W30: 3465.8857 | X30: 427900.93 | Y30: 2498665.8 | Z30: 28.617297
... B36: 80 | C36: 5 | D36: 0.06650611 | E36: 2.5 | F36: 0.28512428 | G36: 0.71487572 | H36: 55675.139 | I36: 15874.334 | J36: 238689.86 | K36: 549104.01 | L36: 9.8626429 | P36: 80 | Q36: 5 | R36: 0.078816557 | S36: 2.5 | T36: 0.329214 | U36: 0.670786 | V36: 42945.465 | W36: 14138.248 | X36: 179381.7 | Y36: 394808.28 | Z36: 9.1932473
B37: 85 | D37: 0.1282184 | F37: 1 | G37: 0 | H37: 39800.805 | I37: 39800.805 | J37: 310414.15 | K37: 310414.15 | L37: 7.7991929 | P37: 85 | R37: 0.13372174 | T37: 1 | U37: 0 | V37: 28807.217 | W37: 28807.217 | X37: 215426.57 | Y37: 215426.57 | Z37: 7.4782156

Sheet Tasas, Gráficos, Mex. y Ver.
G1: Mexico | N1: K
N2: 0.4925
A3: a. Tasas brutas de natalidad | G3: Edad | H3: Punto medio | I3: x | J3: x+n | K3: Nacimientos | L3: Población femenina 30/06/2010 | M3: f(x,5) | N3: % f(x,5) | O3: f(x,5) fem | P3: L(x) fem | Q3: m+2,5P0 | R3: m+2,5P0 * f(x,5)fem
A4: Tasas brutas de natalidad (b) | G4: 15-19 | H4: 17.5 | I4: 15 | J4: 19 | K4: ='Nacimientos y tablas de vida,Me'!C6 -> 315681.16 | L4: ='Nacimientos y tablas de vida,Me'!D6 -> 5363130.5 | M4: =K4/L4 -> 0.05886136 | N4: =M4/$M$11 -> 0.15310177 | O4: =M4*N2 -> 0.02898922 | P4: ='Nacimientos y tablas de vida,Me'!X19 -> 491670 | Q4: =P4/(5*100000) -> 0.98334 | R4: =Q4*O4 -> 0.02850626
A5: Región | B5: Bz | C5: N 30-06-z | D5: b | G5: 20-24 | H5: 22.5 | I5: 20 | J5: 24 | K5: ='Nacimientos y tablas de vida,Me'!C7 -> 545329.57 | L5: ='Nacimientos y tablas de vida,Me'!D7 -> 5235228.6 | M5: =K5/L5 -> 0.10416538 | N5: =M5/$M$11 -> 0.27094013 | O5: =M5*$N$2 -> 0.05130145 | P5: ='Nacimientos y tablas de vida,Me'!X20 -> 490356 | Q5: =P5/(5*100000) -> 0.980712 | R5: =Q5*O5 -> 0.050311948
A6: México | B6: ='Nacimientos y tablas de vida,Me'!C5 -> 1942234 | C6: =Mexico!H37 -> 112336538 | D6: =B6/C6*1000 -> 17.289424 | G6: 25-29 | H6: 27.5 | I6: 25 | J6: 29 | K6: ='Nacimientos y tablas de vida,Me'!C8 -> 511967.39 | L6: ='Nacimientos y tablas de vida,Me'!D8 -> 5064244.9 | M6: =K6/L6 -> 0.10109452 | N6: =M6/$M$11 -> 0.26295263 | O6: =M6*$N$2 -> 0.049789049 | P6: ='Nacimientos y tablas de vida,Me'!X21 -> 488709 | Q6: =P6/(5*100000) -> 0.977418 | R6: =Q6*O6 -> 0.048664713
A7: Veracruz | B7: ='Nacimientos y tablas de vida, V'!C5 -> 109107 | C7: =Veracruz!H37 -> 7643194 | D7: =B7/C7*1000 -> 14.275053 | G7: 30-34 | H7: 32.5 | I7: 30 | J7: 34 | K7: ='Nacimientos y tablas de vida,Me'!C9 -> 347637.04 | L7: ='Nacimientos y tablas de vida,Me'!D9 -> 4838544.7 | M7: =K7/L7 -> 0.071847438 | N7: =M7/$M$11 -> 0.18687931 | O7: =M7*$N$2 -> 0.035384863 | P7: ='Nacimientos y tablas de vida,Me'!X22 -> 486724 | Q7: =P7/(5*100000) -> 0.973448 | R7: =Q7*O7 -> 0.034445324
G8: 35-39 | H8: 37.5 | I8: 35 | J8: 39 | K8: ='Nacimientos y tablas de vida,Me'!C10 -> 174294.23 | L8: ='Nacimientos y tablas de vida,Me'!D10 -> 4645184 | M8: =K8/L8 -> 0.03752149 | N8: =M8/$M$11 -> 0.097595546 | O8: =M8*$N$2 -> 0.018479334 | P8: ='Nacimientos y tablas de vida,Me'!X23 -> 484204 | Q8: =P8/(5*100000) -> 0.968408 | R8: =Q8*O8 -> 0.017895535
A9: b. PMEF | G9: 40-44 | H9: 42.5 | I9: 40 | J9: 44 | K9: ='Nacimientos y tablas de vida,Me'!C11 -> 43848.977 | L9: ='Nacimientos y tablas de vida,Me'!D11 -> 4341995.4 | M9: =K9/L9 -> 0.010098808 | N9: =M9/$M$11 -> 0.026267578 | O9: =M9*$N$2 -> 0.0049736628 | P9: ='Nacimientos y tablas de vida,Me'!X24 -> 480646 | Q9: =P9/(5*100000) -> 0.961292 | R9: =Q9*O9 -> 0.0047811423
A10: Proporción de Mujeres en Edad Fértil | G10: 45-49 | H10: 47.5 | I10: 45 | J10: 49 | K10: ='Nacimientos y tablas de vida,Me'!C12 -> 3475.6292 | L10: ='Nacimientos y tablas de vida,Me'!D12 -> 3994767.7 | M10: =K10/L10 -> 0.00087004539 | N10: =M10/$M$11 -> 0.0022630379 | O10: =M10*$N$2 -> 0.00042849736 | P10: ='Nacimientos y tablas de vida,Me'!X25 -> 475296 | Q10: =P10/(5*100000) -> 0.950592 | R10: =Q10*O10 -> 0.00040732616
A11: País | B11: MEF 30-06-z | C11: N 30-06-z | D11: PMEF | G11: Total | M11: =SUM(M4:M10) -> 0.38445904 | R11: =SUM(R4:R10) -> 0.18501225
A12: México | B12: =SUM(Mexico!P11:P17) -> 33540073 | C12: =Mexico!H37 -> 112336538 | D12: =B12/C12 -> 0.2985678 | L12: TGF | M12: =M11*5 -> 1.9222952
A13: Veracruz | B13: =SUM(Veracruz!P11:P17) -> 2118628.7 | C13: =Veracruz!H37 -> 7643194 | D13: =B13/C13 -> 0.27719154 | L13: TBR | O13: =M12*N2 -> 0.94673038 | Q13: TBR (K obs) | R13: =M12*'Nacimientos y tablas de vida,Me'!H8 -> 0.94456658
H14: México | I14: Veracruz | L14: TNR | R14: =R11*5 -> 0.92506124
A15: c. TFG | G15: TBR | H15: =O13 -> 0.94673038 | I15: =O32 -> 0.86203049
A16: TFG (3 países) | G16: TNR | H16: =R14 -> 0.92506124 | I16: =R33 -> 0.16870314
A17: País | B17: Bz | C17: MEF 30-06-z | D17: TFG | G17: diff | H17: =H15-H16 -> 0.021669144 | I17: =I15-I16 -> 0.69332735
A18: México | B18: =B6 -> 1942234 | C18: =B12 -> 33540073 | D18: =B18/C18*1000 -> 57.907864
A19: Veracruz | B19: =B7 -> 109107 | C19: =B13 -> 2118628.7 | D19: =B19/C19*1000 -> 51.498877
G20: Veracruz
G22: Edad | H22: Punto medio | I22: x | J22: x+n | K22: Nacimientos | L22: Población femenina 30/06/2009 | M22: f(x,5) | N22: % f(x,5) | O22: f(x,5) fem | P22: L(x) fem | Q22: m+2,5P0 | R22: m+2,5P0 * f(x,5)fem
G23: 15-19 | H23: 17.5 | I23: 15 | J23: 19 | K23: ='Nacimientos y tablas de vida, V'!C6 -> 19130.02 | L23: ='Nacimientos y tablas de vida, V'!D6 -> 341902.16 | M23: =K23/L23 -> 0.055951737 | N23: =M23/$M$30 -> 0.15983327 | O23: =M23*N2 -> 0.02755623 | P23: ='Nacimientos y tablas de vida, V'!H23 -> 98368.554 | Q23: =P23/(5*100000) -> 0.19673711 | R23: =Q23*O23 -> 0.005421333
G24: 20-24 | H24: 22.5 | I24: 20 | J24: 24 | K24: ='Nacimientos y tablas de vida, V'!C7 -> 30279.299 | L24: ='Nacimientos y tablas de vida, V'!D7 -> 311014.93 | M24: =K24/L24 -> 0.097356417 | N24: =M24/$M$30 -> 0.27811102 | O24: =M24*$N$2 -> 0.047948035 | P24: ='Nacimientos y tablas de vida, V'!H24 -> 98160.844 | Q24: =P24/(5*100000) -> 0.19632169 | R24: =Q24*O24 -> 0.0094132392
A25: Mexico | G25: 25-29 | H25: 27.5 | I25: 25 | J25: 29 | K25: ='Nacimientos y tablas de vida, V'!C8 -> 28573.709 | L25: ='Nacimientos y tablas de vida, V'!D8 -> 306657.78 | M25: =K25/L25 -> 0.093177838 | N25: =M25/$M$30 -> 0.26617437 | O25: =M25*$N$2 -> 0.045890085 | P25: ='Nacimientos y tablas de vida, V'!H25 -> 97884.415 | Q25: =P25/(5*100000) -> 0.19576883 | R25: =Q25*O25 -> 0.0089838483
A26: Veracruz | G26: 30-34 | H26: 32.5 | I26: 30 | J26: 34 | K26: ='Nacimientos y tablas de vida, V'!C9 -> 19118.852 | L26: ='Nacimientos y tablas de vida, V'!D9 -> 303272.31 | M26: =K26/L26 -> 0.063041865 | N26: =M26/$M$30 -> 0.18008713 | O26: =M26*$N$2 -> 0.031048119 | P26: ='Nacimientos y tablas de vida, V'!H26 -> 97504.702 | Q26: =P26/(5*100000) -> 0.1950094 | R26: =Q26*O26 -> 0.0060546751
G27: 35-39 | H27: 37.5 | I27: 35 | J27: 39 | K27: ='Nacimientos y tablas de vida, V'!C10 -> 9508.6644 | L27: ='Nacimientos y tablas de vida, V'!D10 -> 299156.62 | M27: =K27/L27 -> 0.031784904 | N27: =M27/$M$30 -> 0.090797629 | O27: =M27*$N$2 -> 0.015654065 | P27: ='Nacimientos y tablas de vida, V'!H27 -> 97007.554 | Q27: =P27/(5*100000) -> 0.19401511 | R27: =Q27*O27 -> 0.0030371251
G28: 40-44 | H28: 42.5 | I28: 40 | J28: 44 | K28: ='Nacimientos y tablas de vida, V'!C11 -> 2342.1406 | L28: ='Nacimientos y tablas de vida, V'!D11 -> 286420.8 | M28: =K28/L28 -> 0.0081772714 | N28: =M28/$M$30 -> 0.023359418 | O28: =M28*$N$2 -> 0.0040273061 | P28: ='Nacimientos y tablas de vida, V'!H28 -> 96404.604 | Q28: =P28/(5*100000) -> 0.19280921 | R28: =Q28*O28 -> 0.00077650171
G29: 45-49 | H29: 47.5 | I29: 45 | J29: 49 | K29: ='Nacimientos y tablas de vida, V'!C12 -> 154.31529 | L29: ='Nacimientos y tablas de vida, V'!D12 -> 269258.71 | M29: =K29/L29 -> 0.0005731116 | N29: =M29/$M$30 -> 0.0016371663 | O29: =M29*$N$2 -> 0.00028225746 | P29: ='Nacimientos y tablas de vida, V'!H29 -> 95489.328 | Q29: =P29/(5*100000) -> 0.19097866 | R29: =Q29*O29 -> 5.390515e-05
G30: Total | M30: =SUM(M23:M29) -> 0.35006314 | R30: =SUM(R23:R29) -> 0.033740628
L31: TGF | M31: =M30*5 -> 1.7503157
L32: TBR | O32: =M31*N2 -> 0.86203049 | Q32: TBR (K obs) | R32: =M31*'Nacimientos y tablas de vida, V'!H8 -> 0.86473845
L33: TNR | R33: =R30*5 -> 0.16870314
A35: d. Diferencias relativas de b, TFG, TGF, TBR y TNR de México con respecto a Veracruz
H36: TFG
A37: País | B37: Δ | H37: =D6/D12 -> 57.907864
B38: b | C38: TFG | D38: TGF | E38: TBR | F38: TNR | H38: =D7/D13 -> 51.498877
A39: México-Veracruz | B39: =(D7/D6-1)*100 -> -17.434766 | C39: =(D19/D18-1)*100 -> -11.067559 | D39: =(M31/M12-1)*100 -> -8.9465695 | E39: =(O32/O13-1)*100 -> -8.9465695 | F39: =(R33/R14-1)*100 -> -81.76303
