Workbook
Name Family: #REF!
Name FamSelect: #REF!
Name Princeton: #REF!
Name Sex: #REF!
Name UN: #REF!
Name Variant: #REF!

Sheet Decrementos Múltiples
B2: Hombres, 2019
B3: Age x | C3: n | D3: nDx | E3: nDxi | I3: nqx | K3: e0 | M3: nqx_i | O3: ndx_i | Q3: L | R3: T | S3: e0_i | T3: diff
B4: 0 | C4: 1 | D4: ='Defunciones generales'!C3 -> 731 | E4: =Homicidios!E2 -> 2.0015361 | F4: =(D4-E4)/D4 -> 0.99726192 | G4: ='LT Ver'!G2 -> 100000 | H4: =1-'LT Ver'!E2 -> 0.9870126 | I4: =1-H4 -> 0.012987402 | J4: ='LT Ver'!D2 -> 0.080279593 | K4: ='LT Ver'!K2 -> 72.62802 | L4: =H4^F4 -> 0.98704793 | M4: =1-L4 -> 0.012952072 | N4: 100000 | O4: =N4*M4 -> 1295.2072 | P4: =C4+(F4*(I4/M4)*(J4-C4)) -> 0.080296017 | Q4: =(C4*N5)+(P4*O4) -> 98808.793 | R4: =R5+Q4 -> 7431169.5 | S4: =R4/N4 -> 74.311695 | T4: =S4-K4 -> 1.6836747
B5: 1 | C5: 4 | D5: ='Defunciones generales'!C4 -> 152 | E5: =Homicidios!E3 -> 4.0030722 | F5: =(D5-E5)/D5 -> 0.973664 | G5: ='LT Ver'!G3 -> 98701.26 | H5: =1-'LT Ver'!E3 -> 0.99757261 | I5: =1-H5 -> 0.002427388 | J5: ='LT Ver'!D3 -> 2 | K5: ='LT Ver'!K3 -> 72.582625 | L5: =H5^F5 -> 0.99763646 | M5: =1-L5 -> 0.0023635359 | N5: =N4*L4 -> 98704.793 | O5: =N5*M5 -> 233.29232 | P5: =C5+(F5*(I5/M5)*(J5-C5)) -> 2.000064 | Q5: =(C5*N6)+(P5*O5) -> 394352.6 | R5: =R6+Q5 -> 7332360.7 | S5: =R5/N5 -> 74.285762 | T5: =S5-K5 -> 1.7031369 | V5: Número de años que se espera que viva un hombre de 0 años hasta llegar a los 85 años.
B6: 5 | C6: 5 | D6: ='Defunciones generales'!C5 -> 122 | E6: =Homicidios!E4 -> 1.000768 | F6: =(D6-E6)/D6 -> 0.99179698 | G6: ='LT Ver'!G4 -> 98461.674 | H6: =1-'LT Ver'!E4 -> 0.99846369 | I6: =1-H6 -> 0.0015363076 | J6: ='LT Ver'!D4 -> 2.5 | K6: ='LT Ver'!K4 -> 68.754373 | L6: =H6^F6 -> 0.99847629 | M6: =1-L6 -> 0.0015237148 | N6: =N5*L5 -> 98471.5 | O6: =N6*M6 -> 150.04249 | P6: =C6+(F6*(I6/M6)*(J6-C6)) -> 2.5000158 | Q6: =(C6*N7)+(P6*O6) -> 491982.4 | R6: =R7+Q6 -> 6938008.1 | S6: =R6/N6 -> 70.457016 | T6: =S6-K6 -> 1.7026432
B7: 10 | C7: 5 | D7: ='Defunciones generales'!C6 -> 356 | E7: =Homicidios!E5 -> 8.0061444 | F7: =(D7-E7)/D7 -> 0.97751083 | G7: ='LT Ver'!G5 -> 98310.406 | H7: =1-'LT Ver'!E5 -> 0.99825962 | I7: =1-H7 -> 0.0017403808 | J7: ='LT Ver'!D5 -> 2.5 | K7: ='LT Ver'!K5 -> 63.856317 | L7: =H7^F7 -> 0.99829873 | M7: =1-L7 -> 0.0017012744 | N7: =N6*L6 -> 98321.458 | O7: =N7*M7 -> 167.27178 | P7: =(((-5/24)*O6)+((2.5)*O7)+((5/24)*O8))/O7 -> 2.8700036 | Q7: =(C7*N8)+(P7*O7) -> 491251 | R7: =R8+Q7 -> 6446025.7 | S7: =R7/N7 -> 65.560721 | T7: =S7-K7 -> 1.7044046
B8: 15 | C8: 5 | D8: ='Defunciones generales'!C7 -> 640 | E8: =Homicidios!E6 -> 70.053763 | F8: =(D8-E8)/D8 -> 0.89054099 | G8: ='LT Ver'!G6 -> 98139.309 | H8: =1-'LT Ver'!E6 -> 0.99488625 | I8: =1-H8 -> 0.0051137523 | J8: ='LT Ver'!D6 -> 2.5 | K8: ='LT Ver'!K6 -> 58.963286 | L8: =H8^F8 -> 0.99544472 | M8: =1-L8 -> 0.004555283 | N8: =N7*L7 -> 98154.186 | O8: =N8*M8 -> 447.12009 | P8: =(((-5/24)*O7)+((2.5)*O8)+((5/24)*O9))/O8 -> 2.8036827 | Q8: =(C8*N9)+(P8*O8) -> 489788.91 | R8: =R9+Q8 -> 5954774.7 | S8: =R8/N8 -> 60.667557 | T8: =S8-K8 -> 1.7042709 | V8: Sin COVID | W8: Con COVID
B9: 20 | C9: 5 | D9: ='Defunciones generales'!C8 -> 833 | E9: =Homicidios!E7 -> 189.14516 | F9: =(D9-E9)/D9 -> 0.77293498 | G9: ='LT Ver'!G7 -> 97637.449 | H9: =1-'LT Ver'!E7 -> 0.98916837 | I9: =1-H9 -> 0.010831632 | J9: ='LT Ver'!D7 -> 2.5 | K9: ='LT Ver'!K7 -> 54.25351 | L9: =H9^F9 -> 0.99161751 | M9: =1-L9 -> 0.0083824891 | N9: =N8*L8 -> 97707.066 | O9: =N9*M9 -> 819.02841 | P9: =(((-5/24)*O8)+((2.5)*O9)+((5/24)*O10))/O9 -> 2.6624214 | Q9: =(C9*N10)+(P9*O9) -> 486620.79 | R9: =R10+Q9 -> 5464985.8 | S9: =R9/N9 -> 55.93235 | T9: =S9-K9 -> 1.6788401 | V9: =([1]TV!M53-[1]TV!M71)/[1]TV!J53 -> 66.401396 | W9: =(R4-R22)/N4 -> 72.082845
B10: 25 | C10: 5 | D10: ='Defunciones generales'!C9 -> 834 | E10: =Homicidios!E8 -> 220.16897 | F10: =(D10-E10)/D10 -> 0.73600843 | G10: ='LT Ver'!G8 -> 96579.876 | H10: =1-'LT Ver'!E8 -> 0.98480634 | I10: =1-H10 -> 0.01519366 | J10: ='LT Ver'!D8 -> 2.5 | K10: ='LT Ver'!K8 -> 49.820223 | L10: =H10^F10 -> 0.98879477 | M10: =1-L10 -> 0.011205233 | N10: =N9*L9 -> 96888.038 | O10: =N10*M10 -> 1085.6531 | P10: =(((-5/24)*O9)+((2.5)*O10)+((5/24)*O11))/O10 -> 2.5720389 | Q10: =(C10*N11)+(P10*O10) -> 481804.26 | R10: =R11+Q10 -> 4978365 | S10: =R10/N10 -> 51.382659 | T10: =S10-K10 -> 1.562436 | V10: Diff | W10: =W9-V9 -> 5.6814481
B11: 30 | C11: 5 | D11: ='Defunciones generales'!C10 -> 924 | E11: =Homicidios!E9 -> 194.149 | F11: =(D11-E11)/D11 -> 0.78988203 | G11: ='LT Ver'!G9 -> 95112.474 | H11: =1-'LT Ver'!E9 -> 0.98424203 | I11: =1-H11 -> 0.01575797 | J11: ='LT Ver'!D9 -> 2.5 | K11: ='LT Ver'!K9 -> 45.550283 | L11: =H11^F11 -> 0.98753232 | M11: =1-L11 -> 0.012467675 | N11: =N10*L10 -> 95802.385 | O11: =N11*M11 -> 1194.433 | P11: =(((-5/24)*O10)+((2.5)*O11)+((5/24)*O12))/O11 -> 2.5609824 | Q11: =(C11*N12)+(P11*O11) -> 476098.68 | R11: =R12+Q11 -> 4496560.7 | S11: =R11/N11 -> 46.935791 | T11: =S11-K11 -> 1.3855087
B12: 35 | C12: 5 | D12: ='Defunciones generales'!C11 -> 1077 | E12: =Homicidios!E10 -> 156.11982 | F12: =(D12-E12)/D12 -> 0.85504195 | G12: ='LT Ver'!G10 -> 93613.694 | H12: =1-'LT Ver'!E10 -> 0.98228011 | I12: =1-H12 -> 0.017719888 | J12: ='LT Ver'!D10 -> 2.5 | K12: ='LT Ver'!K10 -> 41.239529 | L12: =H12^F12 -> 0.98482916 | M12: =1-L12 -> 0.015170839 | N12: =N11*L11 -> 94607.952 | O12: =N12*M12 -> 1435.282 | P12: =(((-5/24)*O11)+((2.5)*O12)+((5/24)*O13))/O12 -> 2.5937103 | Q12: =(C12*N13)+(P12*O12) -> 469586.05 | R12: =R13+Q12 -> 4020462.1 | S12: =R12/N12 -> 42.496027 | T12: =S12-K12 -> 1.256498
B13: 40 | C13: 5 | D13: ='Defunciones generales'!C12 -> 1421 | E13: =Homicidios!E11 -> 125.09601 | F13: =(D13-E13)/D13 -> 0.91196622 | G13: ='LT Ver'!G11 -> 91954.87 | H13: =1-'LT Ver'!E11 -> 0.97836572 | I13: =1-H13 -> 0.021634282 | J13: ='LT Ver'!D11 -> 2.5 | K13: ='LT Ver'!K11 -> 36.938372 | L13: =H13^F13 -> 0.98025133 | M13: =1-L13 -> 0.019748672 | N13: =N12*L12 -> 93172.67 | O13: =N13*M13 -> 1840.0365 | P13: =(((-5/24)*O12)+((2.5)*O13)+((5/24)*O14))/O13 -> 2.307998 | Q13: =(C13*N14)+(P13*O13) -> 460909.97 | R13: =R14+Q13 -> 3550876 | S13: =R13/N13 -> 38.110704 | T13: =S13-K13 -> 1.1723313
B14: 45 | C14: 5 | D14: ='Defunciones generales'!C13 -> 106 | E14: =Homicidios!E12 -> 116.08909 | F14: =(D14-E14)/D14 -> -0.095180129 | G14: ='LT Ver'!G12 -> 89965.493 | H14: =1-'LT Ver'!E12 -> 0.970518 | I14: =1-H14 -> 0.029482001 | J14: ='LT Ver'!D12 -> 2.5 | K14: ='LT Ver'!K12 -> 32.699897 | L14: =H14^F14 -> 1.0028524 | M14: =1-L14 -> -0.002852357 | N14: =N13*L13 -> 91332.633 | O14: =N14*M14 -> -260.51328 | P14: =(((-5/24)*O13)+((2.5)*O14)+((5/24)*O15))/O14 -> 1.1884944 | Q14: =(C14*N15)+(P14*O14) -> 457656.11 | R14: =R15+Q14 -> 3089966 | S14: =R14/N14 -> 33.832004 | T14: =S14-K14 -> 1.1321074
B15: 50 | C15: 5 | D15: ='Defunciones generales'!C14 -> 1810 | E15: =Homicidios!E13 -> 79.060676 | F15: =(D15-E15)/D15 -> 0.95632007 | G15: ='LT Ver'!G13 -> 87313.13 | H15: =1-'LT Ver'!E13 -> 0.9603051 | I15: =1-H15 -> 0.039694898 | J15: ='LT Ver'!D13 -> 2.5 | K15: ='LT Ver'!K13 -> 28.617297 | L15: =H15^F15 -> 0.9620056 | M15: =1-L15 -> 0.037994401 | N15: =N14*L14 -> 91593.146 | O15: =N15*M15 -> 3480.0267 | P15: =(((-5/24)*O14)+((2.5)*O15)+((5/24)*O16))/O15 -> 2.8110531 | Q15: =(C15*N16)+(P15*O15) -> 450348.14 | R15: =R16+Q15 -> 2632309.9 | S15: =R15/N15 -> 28.739158 | T15: =S15-K15 -> 0.12186113
B16: 55 | C16: 5 | D16: ='Defunciones generales'!C15 -> 2225 | E16: =Homicidios!E14 -> 51.039171 | F16: =(D16-E16)/D16 -> 0.97706105 | G16: ='LT Ver'!G14 -> 83847.244 | H16: =1-'LT Ver'!E14 -> 0.94271178 | I16: =1-H16 -> 0.05728822 | J16: ='LT Ver'!D14 -> 2.5 | K16: ='LT Ver'!K14 -> 24.696874 | L16: =H16^F16 -> 0.94398839 | M16: =1-L16 -> 0.056011607 | N16: =N15*L15 -> 88113.12 | O16: =N16*M16 -> 4935.3574 | P16: =(((-5/24)*O15)+((2.5)*O16)+((5/24)*O17))/O16 -> 2.6348309 | Q16: =(C16*N17)+(P16*O16) -> 428892.64 | R16: =R17+Q16 -> 2181961.8 | S16: =R16/N16 -> 24.763188 | T16: =S16-K16 -> 0.066314229
B17: 60 | C17: 5 | D17: ='Defunciones generales'!C16 -> 2691 | E17: =Homicidios!E15 -> 32.024578 | F17: =(D17-E17)/D17 -> 0.98809938 | G17: ='LT Ver'!G15 -> 79043.785 | H17: =1-'LT Ver'!E15 -> 0.91883455 | I17: =1-H17 -> 0.081165453 | J17: ='LT Ver'!D15 -> 2.5 | K17: ='LT Ver'!K15 -> 21.045769 | L17: =H17^F17 -> 0.91976063 | M17: =1-L17 -> 0.080239372 | N17: =N16*L16 -> 83177.762 | O17: =N17*M17 -> 6674.1314 | P17: =(((-5/24)*O16)+((2.5)*O17)+((5/24)*O18))/O17 -> 2.5948539 | Q17: =(C17*N18)+(P17*O17) -> 399836.55 | R17: =R18+Q17 -> 1753069.1 | S17: =R17/N17 -> 21.076176 | T17: =S17-K17 -> 0.030406409
B18: 65 | C18: 5 | D18: ='Defunciones generales'!C17 -> 2820 | E18: =Homicidios!E16 -> 24.018433 | F18: =(D18-E18)/D18 -> 0.99148283 | G18: ='LT Ver'!G16 -> 72628.16 | H18: =1-'LT Ver'!E16 -> 0.89492197 | I18: =1-H18 -> 0.10507803 | J18: ='LT Ver'!D16 -> 2.5 | K18: ='LT Ver'!K16 -> 17.684014 | L18: =H18^F18 -> 0.89576858 | M18: =1-L18 -> 0.10423142 | N18: =N17*L17 -> 76503.631 | O18: =N18*M18 -> 7974.0819 | P18: =(((-5/24)*O17)+((2.5)*O18)+((5/24)*O19))/O18 -> 2.5960507 | Q18: =(C18*N19)+(P18*O18) -> 363348.87 | R18: =R19+Q18 -> 1353232.6 | S18: =R18/N18 -> 17.688475 | T18: =S18-K18 -> 0.004461345
B19: 70 | C19: 5 | D19: ='Defunciones generales'!C18 -> 3079 | E19: =Homicidios!E17 -> 18.013825 | F19: =(D19-E19)/D19 -> 0.99414946 | G19: ='LT Ver'!G17 -> 64996.536 | H19: =1-'LT Ver'!E17 -> 0.84814484 | I19: =1-H19 -> 0.15185516 | J19: ='LT Ver'!D17 -> 2.5 | K19: ='LT Ver'!K17 -> 14.466858 | L19: =H19^F19 -> 0.84896251 | M19: =1-L19 -> 0.15103749 | N19: =N18*L18 -> 68529.549 | O19: =N19*M19 -> 10350.531 | P19: =(((-5/24)*O18)+((2.5)*O19)+((5/24)*O20))/O19 -> 2.5977739 | Q19: =(C19*N20)+(P19*O19) -> 317783.43 | R19: =R20+Q19 -> 989883.73 | S19: =R19/N19 -> 14.444626 | T19: =S19-K19 -> -0.022231679
B20: 75 | C20: 5 | D20: ='Defunciones generales'!C19 -> 3335 | E20: =Homicidios!E18 -> 7.0053763 | F20: =(D20-E20)/D20 -> 0.99789944 | G20: ='LT Ver'!G18 -> 55126.477 | H20: =1-'LT Ver'!E18 -> 0.77903518 | I20: =1-H20 -> 0.22096482 | J20: ='LT Ver'!D18 -> 2.5 | K20: ='LT Ver'!K18 -> 11.609451 | L20: =H20^F20 -> 0.77944389 | M20: =1-L20 -> 0.22055611 | N20: =N19*L19 -> 58179.018 | O20: =N20*M20 -> 12831.738 | P20: =(((-5/24)*O19)+((2.5)*O20)+((5/24)*O21))/O20 -> 2.5741548 | Q20: =(C20*N21)+(P20*O20) -> 259767.28 | R20: =R21+Q20 -> 672100.3 | S20: =R20/N20 -> 11.55228 | T20: =S20-K20 -> -0.057171085
B21: 80 | C21: 5 | D21: ='Defunciones generales'!C20 -> 3298 | E21: =Homicidios!E19 -> 3.0023041 | F21: =(D21-E21)/D21 -> 0.99908966 | G21: ='LT Ver'!G19 -> 42945.465 | H21: =1-'LT Ver'!E19 -> 0.670786 | I21: =1-H21 -> 0.329214 | J21: ='LT Ver'!D19 -> 2.5 | K21: ='LT Ver'!K19 -> 9.1932473 | L21: =H21^F21 -> 0.67102988 | M21: =1-L21 -> 0.32897012 | N21: =N20*L20 -> 45347.28 | O21: =N21*M21 -> 14917.9 | P21: =C21+(F21*(I21/M21)*(J21-C21)) -> 2.5004242 | Q21: =(C21*N22)+(P21*O21) -> 189447.98 | R21: =R22+Q21 -> 412333.02 | S21: =R21/N21 -> 9.0927839 | T21: =S21-K21 -> -0.10046345
B22: 85 | C22: 5 | D22: ='Defunciones generales'!C21 -> 4797 | E22: =Homicidios!E20 -> 3.0023041 | F22: =(D22-E22)/D22 -> 0.99937413 | G22: ='LT Ver'!G20 -> 28807.217 | H22: =1-'LT Ver'!E20 -> 0 | I22: =1-H22 -> 1 | J22: ='LT Ver'!D20 -> 0 | K22: ='LT Ver'!K20 -> 7.4782156 | L22: =H22^F22 -> 0 | M22: =1-L22 -> 1 | N22: =N21*L21 -> 30429.38 | O22: =N22*M22 -> 30429.38 | P22: =K22/F22 -> 7.4828989 | Q22: 222885.04 | R22: =Q22 -> 222885.04 | S22: =R22/N22 -> 7.3246658 | T22: =S22-K22 -> -0.15354974
B24: Mujeres, 2019
B26: Age x | C26: n | D26: nDx | E26: nDxi | I26: nqx | K26: e0 | M26: nqx_i | O26: ndx_i | Q26: L | R26: T | S26: e0_i | T26: diff | AA26: Hombres | AB26: Mujeres
B27: 0 | C27: 1 | D27: ='Defunciones generales'!D3 -> 643 | E27: =Homicidios!J2 -> 0 | F27: =(D27-E27)/D27 -> 1 | G27: ='LT Ver'!G25 -> 100000 | H27: =1-'LT Ver'!E25 -> 0.98834188 | I27: =1-H27 -> 0.011658117 | J27: ='LT Ver'!D25 -> 0.085994301 | K27: ='LT Ver'!K25 -> 78.39635 | L27: =H27^F27 -> 0.98834188 | M27: =1-L27 -> 0.011658117 | N27: 100000 | O27: =N27*M27 -> 1165.8117 | P27: =C27+(F27*(I27/M27)*(J27-C27)) -> 0.085994301 | Q27: =(C27*N28)+(P27*O27) -> 98934.441 | R27: =R28+Q27 -> 7859270.7 | S27: =R27/N27 -> 78.592707 | T27: =S27-K27 -> 0.1963566 | Z27: Sin homicidios | AA27: =S4 -> 74.311695 | AB27: =S27 -> 78.592707
B28: 1 | C28: 4 | D28: ='Defunciones generales'!D4 -> 135 | E28: =Homicidios!J3 -> 0 | F28: =(D28-E28)/D28 -> 1 | G28: ='LT Ver'!G26 -> 98834.188 | H28: =1-'LT Ver'!E26 -> 0.99779816 | I28: =1-H28 -> 0.0022018438 | J28: ='LT Ver'!D26 -> 2 | K28: ='LT Ver'!K26 -> 78.320071 | L28: =H28^F28 -> 0.99779816 | M28: =1-L28 -> 0.0022018438 | N28: =N27*L27 -> 98834.188 | O28: =N28*M28 -> 217.61745 | P28: =C28+(F28*(I28/M28)*(J28-C28)) -> 2 | Q28: =(C28*N29)+(P28*O28) -> 394901.52 | R28: =R29+Q28 -> 7760336.3 | S28: =R28/N28 -> 78.518743 | T28: =S28-K28 -> 0.19867275 | V28: Número de años que se espera que viva una mujer de 0 años hasta llegar a los 85 años. | Z28: Con homicidios | AA28: =K4 -> 72.62802 | AB28: =K27 -> 78.39635
B29: 5 | C29: 5 | D29: ='Defunciones generales'!D5 -> 84 | E29: =Homicidios!J4 -> 0 | F29: =(D29-E29)/D29 -> 1 | G29: ='LT Ver'!G27 -> 98616.571 | H29: =1-'LT Ver'!E27 -> 0.99871764 | I29: =1-H29 -> 0.0012823648 | J29: ='LT Ver'!D27 -> 2.5 | K29: ='LT Ver'!K27 -> 74.488486 | L29: =H29^F29 -> 0.99871764 | M29: =1-L29 -> 0.0012823648 | N29: =N28*L28 -> 98616.571 | O29: =N29*M29 -> 126.46242 | P29: =C29+(F29*(I29/M29)*(J29-C29)) -> 2.5 | Q29: =(C29*N30)+(P29*O29) -> 492766.7 | R29: =R30+Q29 -> 7365434.7 | S29: =R29/N29 -> 74.687597 | T29: =S29-K29 -> 0.19911117 | AA29: =AA27-AA28 -> 1.6836747 | AB29: =AB27-AB28 -> 0.1963566
B30: 10 | C30: 5 | D30: ='Defunciones generales'!D6 -> 144 | E30: =Homicidios!J5 -> 4 | F30: =(D30-E30)/D30 -> 0.97222222 | G30: ='LT Ver'!G28 -> 98490.108 | H30: =1-'LT Ver'!E28 -> 0.99876582 | I30: =1-H30 -> 0.0012341834 | J30: ='LT Ver'!D28 -> 2.5 | K30: ='LT Ver'!K28 -> 69.58092 | L30: =H30^F30 -> 0.99880008 | M30: =1-L30 -> 0.0011999211 | N30: =N29*L29 -> 98490.108 | O30: =N30*M30 -> 118.18036 | P30: =(((-5/24)*O29)+((2.5)*O30)+((5/24)*O31))/O30 -> 2.6139738 | Q30: =(C30*N31)+(P30*O30) -> 492168.56 | R30: =R31+Q30 -> 6872668 | S30: =R30/N30 -> 69.780287 | T30: =S30-K30 -> 0.19936683
B31: 15 | C31: 5 | D31: ='Defunciones generales'!D7 -> 175 | E31: =Homicidios!J6 -> 14 | F31: =(D31-E31)/D31 -> 0.92 | G31: ='LT Ver'!G29 -> 98368.554 | H31: =1-'LT Ver'!E29 -> 0.99788845 | I31: =1-H31 -> 0.0021115484 | J31: ='LT Ver'!D29 -> 2.5 | K31: ='LT Ver'!K29 -> 64.663813 | L31: =H31^F31 -> 0.99805721 | M31: =1-L31 -> 0.0019427887 | N31: =N30*L30 -> 98371.928 | O31: =N31*M31 -> 191.11587 | P31: =(((-5/24)*O30)+((2.5)*O31)+((5/24)*O32))/O31 -> 2.6448585 | Q31: =(C31*N32)+(P31*O31) -> 491409.54 | R31: =R32+Q31 -> 6380499.5 | S31: =R31/N31 -> 64.860978 | T31: =S31-K31 -> 0.19716546 | V31: Sin COVID | W31: Con COVID
B32: 20 | C32: 5 | D32: ='Defunciones generales'!D8 -> 239 | E32: =Homicidios!J7 -> 22 | F32: =(D32-E32)/D32 -> 0.90794979 | G32: ='LT Ver'!G30 -> 98160.844 | H32: =1-'LT Ver'!E30 -> 0.99718392 | I32: =1-H32 -> 0.0028160809 | J32: ='LT Ver'!D30 -> 2.5 | K32: ='LT Ver'!K30 -> 59.795352 | L32: =H32^F32 -> 0.99744281 | M32: =1-L32 -> 0.0025571918 | N32: =N31*L31 -> 98180.812 | O32: =N32*M32 -> 251.06717 | P32: =(((-5/24)*O31)+((2.5)*O32)+((5/24)*O33))/O32 -> 2.6283115 | Q32: =(C32*N33)+(P32*O32) -> 490308.61 | R32: =R33+Q32 -> 5889089.9 | S32: =R32/N32 -> 59.982086 | T32: =S32-K32 -> 0.18673388 | V32: =([1]TV!M29-[1]TV!M47)/[1]TV!J29 -> 73.3257 | W32: =(R27-R45)/N27 -> 75.47635
B33: 25 | C33: 5 | D33: ='Defunciones generales'!D9 -> 311 | E33: =Homicidios!J8 -> 28 | F33: =(D33-E33)/D33 -> 0.90996785 | G33: ='LT Ver'!G31 -> 97884.415 | H33: =1-'LT Ver'!E31 -> 0.9961208 | I33: =1-H33 -> 0.0038791963 | J33: ='LT Ver'!D31 -> 2.5 | K33: ='LT Ver'!K31 -> 54.957156 | L33: =H33^F33 -> 0.99646944 | M33: =1-L33 -> 0.0035305612 | N33: =N32*L32 -> 97929.745 | O33: =N33*M33 -> 345.74696 | P33: =(((-5/24)*O32)+((2.5)*O33)+((5/24)*O34))/O33 -> 2.6317285 | Q33: =(C33*N34)+(P33*O33) -> 488829.9 | R33: =R34+Q33 -> 5398781.3 | S33: =R33/N33 -> 55.129127 | T33: =S33-K33 -> 0.17197049 | V33: Diff | W33: =W32-V32 -> 2.1506498
B34: 30 | C34: 5 | D34: ='Defunciones generales'!D10 -> 374 | E34: =Homicidios!J9 -> 21 | F34: =(D34-E34)/D34 -> 0.94385027 | G34: ='LT Ver'!G32 -> 97504.702 | H34: =1-'LT Ver'!E32 -> 0.9949013 | I34: =1-H34 -> 0.0050987034 | J34: ='LT Ver'!D32 -> 2.5 | K34: ='LT Ver'!K32 -> 50.16144 | L34: =H34^F34 -> 0.9951869 | M34: =1-L34 -> 0.0048131026 | N34: =N33*L33 -> 97583.998 | O34: =N34*M34 -> 469.6818 | P34: =(((-5/24)*O33)+((2.5)*O34)+((5/24)*O35))/O34 -> 2.6066147 | Q34: =(C34*N35)+(P34*O34) -> 486795.86 | R34: =R35+Q34 -> 4909951.4 | S34: =R34/N34 -> 50.315129 | T34: =S34-K34 -> 0.15368839
B35: 35 | C35: 5 | D35: ='Defunciones generales'!D11 -> 550 | E35: =Homicidios!J10 -> 16 | F35: =(D35-E35)/D35 -> 0.97090909 | G35: ='LT Ver'!G33 -> 97007.554 | H35: =1-'LT Ver'!E33 -> 0.99378451 | I35: =1-H35 -> 0.0062154949 | J35: ='LT Ver'!D33 -> 2.5 | K35: ='LT Ver'!K33 -> 45.405697 | L35: =H35^F35 -> 0.99396477 | M35: =1-L35 -> 0.0060352272 | N35: =N34*L34 -> 97114.316 | O35: =N35*M35 -> 586.10696 | P35: =(((-5/24)*O34)+((2.5)*O35)+((5/24)*O36))/O35 -> 2.6502331 | Q35: =(C35*N36)+(P35*O35) -> 484194.37 | R35: =R36+Q35 -> 4423155.6 | S35: =R35/N35 -> 45.545865 | T35: =S35-K35 -> 0.14016799
B36: 40 | C36: 5 | D36: ='Defunciones generales'!D12 -> 870 | E36: =Homicidios!J11 -> 23 | F36: =(D36-E36)/D36 -> 0.97356322 | G36: ='LT Ver'!G34 -> 96404.604 | H36: =1-'LT Ver'!E34 -> 0.99050588 | I36: =1-H36 -> 0.0094941188 | J36: ='LT Ver'!D34 -> 2.5 | K36: ='LT Ver'!K34 -> 40.674045 | L36: =H36^F36 -> 0.99075571 | M36: =1-L36 -> 0.0092442886 | N36: =N35*L35 -> 96528.209 | O36: =N36*M36 -> 892.33463 | P36: =(((-5/24)*O35)+((2.5)*O36)+((5/24)*O37))/O36 -> 2.6845443 | Q36: =(C36*N37)+(P36*O36) -> 480574.89 | R36: =R37+Q36 -> 3938961.2 | S36: =R36/N36 -> 40.806322 | T36: =S36-K36 -> 0.13227673
B37: 45 | C37: 5 | D37: ='Defunciones generales'!D13 -> 86 | E37: =Homicidios!J12 -> 8 | F37: =(D37-E37)/D37 -> 0.90697674 | G37: ='LT Ver'!G35 -> 95489.328 | H37: =1-'LT Ver'!E35 -> 0.98414186 | I37: =1-H37 -> 0.015858144 | J37: ='LT Ver'!D35 -> 2.5 | K37: ='LT Ver'!K35 -> 36.039948 | L37: =H37^F37 -> 0.98560636 | M37: =1-L37 -> 0.014393639 | N37: =N36*L36 -> 95635.875 | O37: =N37*M37 -> 1376.5482 | P37: =(((-5/24)*O36)+((2.5)*O37)+((5/24)*O38))/O37 -> 2.6706751 | Q37: =(C37*N38)+(P37*O37) -> 474972.95 | R37: =R38+Q37 -> 3458386.3 | S37: =R37/N37 -> 36.162019 | T37: =S37-K37 -> 0.12207077
B38: 50 | C38: 5 | D38: ='Defunciones generales'!D14 -> 1114 | E38: =Homicidios!J13 -> 7 | F38: =(D38-E38)/D38 -> 0.99371634 | G38: ='LT Ver'!G36 -> 93975.044 | H38: =1-'LT Ver'!E36 -> 0.97843509 | I38: =1-H38 -> 0.021564908 | J38: ='LT Ver'!D36 -> 2.5 | K38: ='LT Ver'!K36 -> 31.5804 | L38: =H38^F38 -> 0.97856914 | M38: =1-L38 -> 0.021430864 | N38: =N37*L37 -> 94259.326 | O38: =N38*M38 -> 2020.0588 | P38: =(((-5/24)*O37)+((2.5)*O38)+((5/24)*O39))/O38 -> 2.7081631 | Q38: =(C38*N39)+(P38*O38) -> 466666.99 | R38: =R39+Q38 -> 2983413.4 | S38: =R38/N38 -> 31.651121 | T38: =S38-K38 -> 0.070721125
B39: 55 | C39: 5 | D39: ='Defunciones generales'!D15 -> 1592 | E39: =Homicidios!J14 -> 7 | F39: =(D39-E39)/D39 -> 0.99560302 | G39: ='LT Ver'!G37 -> 91948.481 | H39: =1-'LT Ver'!E37 -> 0.96303451 | I39: =1-H39 -> 0.036965486 | J39: ='LT Ver'!D37 -> 2.5 | K39: ='LT Ver'!K37 -> 27.221338 | L39: =H39^F39 -> 0.96319402 | M39: =1-L39 -> 0.036805978 | N39: =N38*L38 -> 92239.268 | O39: =N39*M39 -> 3394.9565 | P39: =(((-5/24)*O38)+((2.5)*O39)+((5/24)*O40))/O39 -> 2.6792328 | Q39: =(C39*N40)+(P39*O39) -> 453317.43 | R39: =R40+Q39 -> 2516746.4 | S39: =R39/N39 -> 27.284978 | T39: =S39-K39 -> 0.063639898
B40: 60 | C40: 5 | D40: ='Defunciones generales'!D16 -> 2063 | E40: =Homicidios!J15 -> 4 | F40: =(D40-E40)/D40 -> 0.99806108 | G40: ='LT Ver'!G38 -> 88549.561 | H40: =1-'LT Ver'!E38 -> 0.94428315 | I40: =1-H40 -> 0.055716851 | J40: ='LT Ver'!D38 -> 2.5 | K40: ='LT Ver'!K38 -> 23.170251 | L40: =H40^F40 -> 0.94438812 | M40: =1-L40 -> 0.055611882 | N40: =N39*L39 -> 88844.311 | O40: =N40*M40 -> 4940.7993 | P40: =(((-5/24)*O39)+((2.5)*O40)+((5/24)*O41))/O40 -> 2.639217 | Q40: =(C40*N41)+(P40*O40) -> 432557.4 | R40: =R41+Q40 -> 2063429 | S40: =R40/N40 -> 23.225223 | T40: =S40-K40 -> 0.054971736
B41: 65 | C41: 5 | D41: ='Defunciones generales'!D17 -> 2402 | E41: =Homicidios!J16 -> 6 | F41: =(D41-E41)/D41 -> 0.99750208 | G41: ='LT Ver'!G39 -> 83615.858 | H41: =1-'LT Ver'!E39 -> 0.9199952 | I41: =1-H41 -> 0.080004796 | J41: ='LT Ver'!D39 -> 2.5 | K41: ='LT Ver'!K39 -> 19.389887 | L41: =H41^F41 -> 0.92018685 | M41: =1-L41 -> 0.079813147 | N41: =N40*L40 -> 83903.512 | O41: =N41*M41 -> 6696.6034 | P41: =(((-5/24)*O40)+((2.5)*O41)+((5/24)*O42))/O41 -> 2.6288233 | Q41: =(C41*N42)+(P41*O41) -> 403638.73 | R41: =R42+Q41 -> 1630871.6 | S41: =R41/N41 -> 19.437465 | T41: =S41-K41 -> 0.047577735
B42: 70 | C42: 5 | D42: ='Defunciones generales'!D18 -> 2648 | E42: =Homicidios!J17 -> 3 | F42: =(D42-E42)/D42 -> 0.99886707 | G42: ='LT Ver'!G40 -> 76926.188 | H42: =1-'LT Ver'!E40 -> 0.88224726 | I42: =1-H42 -> 0.11775274 | J42: ='LT Ver'!D40 -> 2.5 | K42: ='LT Ver'!K40 -> 15.858669 | L42: =H42^F42 -> 0.8823725 | M42: =1-L42 -> 0.1176275 | N42: =N41*L41 -> 77206.909 | O42: =N42*M42 -> 9081.656 | P42: =(((-5/24)*O41)+((2.5)*O42)+((5/24)*O43))/O42 -> 2.6269711 | Q42: =(C42*N43)+(P42*O42) -> 364483.51 | R42: =R43+Q42 -> 1227232.8 | S42: =R42/N42 -> 15.895376 | T42: =S42-K42 -> 0.036707244
B43: 75 | C43: 5 | D43: ='Defunciones generales'!D19 -> 2956 | E43: =Homicidios!J18 -> 2 | F43: =(D43-E43)/D43 -> 0.99932341 | G43: ='LT Ver'!G41 -> 67867.919 | H43: =1-'LT Ver'!E41 -> 0.82034545 | I43: =1-H43 -> 0.17965455 | J43: ='LT Ver'!D41 -> 2.5 | K43: ='LT Ver'!K41 -> 12.641638 | L43: =H43^F43 -> 0.82045537 | M43: =1-L43 -> 0.17954463 | N43: =N42*L42 -> 68125.253 | O43: =N43*M43 -> 12231.523 | P43: =(((-5/24)*O42)+((2.5)*O43)+((5/24)*O44))/O43 -> 2.61669 | Q43: =(C43*N44)+(P43*O43) -> 311474.75 | R43: =R44+Q43 -> 862749.32 | S43: =R43/N43 -> 12.664163 | T43: =S43-K43 -> 0.02252532
...

Sheet Base defun. por homi
A1: Base de datos de Defunciones por homicidios de Veracruz
A6: Edad | B6: Año | C6: Filtro_Total | D6: Total_Muertes | E6: Hombre | F6: Mujer | G6: Sexo_No_Especificado
A7: Total | B7: 1990 | C7: Total | D7: 759 | E7: 696 | F7: 62 | G7: 1
A8: Total | B8: 1991 | C8: Total | D8: 850 | E8: 778 | F8: 72
A9: Total | B9: 1992 | C9: Total | D9: 733 | E9: 668 | F9: 63 | G9: 2
A10: Total | B10: 1993 | C10: Total | D10: 706 | E10: 645 | F10: 61
A11: Total | B11: 1994 | C11: Total | D11: 696 | E11: 644 | F11: 52
A12: Total | B12: 1995 | C12: Total | D12: 633 | E12: 568 | F12: 63 | G12: 2
A13: Total | B13: 1996 | C13: Total | D13: 564 | E13: 518 | F13: 46
A14: Total | B14: 1997 | C14: Total | D14: 651 | E14: 577 | F14: 74
A15: Total | B15: 1998 | C15: Total | D15: 526 | E15: 474 | F15: 52
A16: Total | B16: 1999 | C16: Total | D16: 454 | E16: 404 | F16: 50
A17: Total | B17: 2000 | C17: Total | D17: 433 | E17: 387 | F17: 46
A18: Total | B18: 2001 | C18: Total | D18: 412 | E18: 360 | F18: 52
A19: Total | B19: 2002 | C19: Total | D19: 368 | E19: 316 | F19: 51 | G19: 1
A20: Total | B20: 2003 | C20: Total | D20: 407 | E20: 356 | F20: 51
A21: Total | B21: 2004 | C21: Total | D21: 345 | E21: 302 | F21: 43
A22: Total | B22: 2005 | C22: Total | D22: 356 | E22: 307 | F22: 49
A23: Total | B23: 2006 | C23: Total | D23: 368 | E23: 320 | F23: 48
A24: Total | B24: 2007 | C24: Total | D24: 375 | E24: 328 | F24: 47
A25: Total | B25: 2008 | C25: Total | D25: 377 | E25: 316 | F25: 61
A26: Total | B26: 2009 | C26: Total | D26: 713 | E26: 605 | F26: 107 | G26: 1
A27: Total | B27: 2010 | C27: Total | D27: 497 | E27: 431 | F27: 65 | G27: 1
A28: Total | B28: 2011 | C28: Total | D28: 1011 | E28: 860 | F28: 145 | G28: 6
A29: Total | B29: 2012 | C29: Total | D29: 1028 | E29: 876 | F29: 139 | G29: 13
A30: Total | B30: 2013 | C30: Total | D30: 794 | E30: 690 | F30: 100 | G30: 4
A31: Total | B31: 2014 | C31: Total | D31: 923 | E31: 820 | F31: 99 | G31: 4
A32: Total | B32: 2015 | C32: Total | D32: 1041 | E32: 926 | F32: 113 | G32: 2
A33: Total | B33: 2016 | C33: Total | D33: 1321 | E33: 1166 | F33: 150 | G33: 5
A34: Total | B34: 2017 | C34: Total | D34: 1825 | E34: 1615 | F34: 210
A35: Total | B35: 2018 | C35: Total | D35: 1487 | E35: 1344 | F35: 143
A36: Total | B36: 2019 | C36: Total | D36: 1470 | E36: 1303 | F36: 167
A37: Total | B37: 2020 | C37: Total | D37: 1223 | E37: 1080 | F37: 143
A38: Total | B38: 2021 | C38: Total | D38: 961 | E38: 850 | F38: 111
A39: Total | B39: 2022 | C39: Total | D39: 812 | E39: 700 | F39: 112
A40: Total | B40: 2023 | C40: Total | D40: 840 | E40: 744 | F40: 94 | G40: 2
A41: Total | B41: 2024 | C41: Total | D41: 869 | E41: 759 | F41: 110
A42: 0 | B42: 1990 | C42: Total | D42: 2 | E42: 2
A43: 0 | B43: 1991 | C43: Total | D43: 4 | E43: 3 | F43: 1
A44: 0 | B44: 1992 | C44: Total | D44: 2 | E44: 2
...

Sheet Tabla din. defun. x homi
A1: Año | B1: 2019
A3: Etiquetas de fila | B3: Suma de Hombre | C3: Suma de Mujer | D3: Suma de Sexo_No_Especificado | E3: Suma de Total_Muertes
A4: 0 | B4: 2 | E4: 2
A5: 1 | B5: 4 | E5: 4
A6: 5 | B6: 1 | E6: 1
A7: 10 | B7: 8 | C7: 4 | E7: 12
A8: 15 | B8: 70 | C8: 14 | E8: 84
A9: 20 | B9: 189 | C9: 22 | E9: 211
A10: 25 | B10: 220 | C10: 28 | E10: 248
A11: 30 | B11: 194 | C11: 21 | E11: 215
A12: 35 | B12: 156 | C12: 16 | E12: 172
A13: 40 | B13: 125 | C13: 23 | E13: 148
A14: 45 | B14: 116 | C14: 8 | E14: 124
A15: 50 | B15: 79 | C15: 7 | E15: 86
A16: 55 | B16: 51 | C16: 7 | E16: 58
A17: 60 | B17: 32 | C17: 4 | E17: 36
A18: 65 | B18: 24 | C18: 6 | E18: 30
... A22: 85 | B22: 3 | C22: 1 | E22: 4
A23: No especificado | B23: 1 | E23: 1
A24: Total | B24: 1303 | C24: 167 | E24: 1470
A25: Total general | B25: 2606 | C25: 334 | E25: 2940

Sheet Prorrateo
A1: Edad | B1: Hombre | C1: Mujer | D1: Sexo No esp | E1: total | H1: Hombre | I1: Mujer | K1: PRORRATEO | L1: Hombre | M1: Mujer
A2: 0 | B2: 2 | E2: 2 | G2: 0 | H2: =B2 * (E2 / (B2 + C2)) -> 2 | I2: =C2 * (E2 / (B2 + C2)) -> 0 | K2: 0 | L2: =H2+(H$2/SUM(H$2:H$20)*H$21) -> 2.0320739 | M2: =I2+(I2/SUM(I$2:I$20)*I$21) -> 0
A3: 1 | B3: 1 | C3: 2 | E3: 3 | G3: 1 | H3: =B3 * (E3 / (B3 + C3)) -> 1 | I3: =C3 * (E3 / (B3 + C3)) -> 2 | K3: 1 | L3: =H3+(H3/SUM(H$2:H$20)*H$21) -> 1.016037 | M3: =I3+(I3/SUM(I$2:I$20)*I$21) -> 2.0665731
A4: 5 | B4: 9 | C4: 1 | E4: 10 | G4: 5 | H4: =B4 * (E4 / (B4 + C4)) -> 9 | I4: =C4 * (E4 / (B4 + C4)) -> 1 | K4: 5 | L4: =H4+(H4/SUM(H$2:H$20)*H$21) -> 9.1443326 | M4: =I4+(I4/SUM(I$2:I$20)*I$21) -> 1.0332865
A5: 10 | B5: 5 | C5: 3 | E5: 8 | G5: 10 | H5: =B5 * (E5 / (B5 + C5)) -> 5 | I5: =C5 * (E5 / (B5 + C5)) -> 3 | K5: 10 | L5: =H5+(H5/SUM(H$2:H$20)*H$21) -> 5.0801848 | M5: =I5+(I5/SUM(I$2:I$20)*I$21) -> 3.0998596
A6: 15 | B6: 48 | C6: 4 | E6: 52 | G6: 15 | H6: =B6 * (E6 / (B6 + C6)) -> 48 | I6: =C6 * (E6 / (B6 + C6)) -> 4 | K6: 15 | L6: =H6+(H6/SUM(H$2:H$20)*H$21) -> 48.769774 | M6: =I6+(I6/SUM(I$2:I$20)*I$21) -> 4.1331462
A7: 20 | B7: 94 | C7: 7 | E7: 101 | G7: 20 | H7: =B7 * (E7 / (B7 + C7)) -> 94 | I7: =C7 * (E7 / (B7 + C7)) -> 7 | K7: 20 | L7: =H7+(H7/SUM(H$2:H$20)*H$21) -> 95.507474 | M7: =I7+(I7/SUM(I$2:I$20)*I$21) -> 7.2330058
A8: 25 | B8: 102 | C8: 11 | E8: 113 | G8: 25 | H8: =B8 * (E8 / (B8 + C8)) -> 102 | I8: =C8 * (E8 / (B8 + C8)) -> 11 | K8: 25 | L8: =H8+(H8/SUM(H$2:H$20)*H$21) -> 103.63577 | M8: =I8+(I8/SUM(I$2:I$20)*I$21) -> 11.366152
A9: 30 | B9: 76 | C9: 7 | D9: 1 | E9: 84 | G9: 30 | H9: =B9 * (E9 / (B9 + C9)) -> 76.915663 | I9: =C9 * (E9 / (B9 + C9)) -> 7.0843373 | K9: 30 | L9: =H9+(H9/SUM(H$2:H$20)*H$21) -> 78.149156 | M9: =I9+(I9/SUM(I$2:I$20)*I$21) -> 7.3201505
A10: 35 | B10: 86 | C10: 4 | E10: 90 | G10: 35 | H10: =B10 * (E10 / (B10 + C10)) -> 86 | I10: =C10 * (E10 / (B10 + C10)) -> 4 | K10: 35 | L10: =H10+(H10/SUM(H$2:H$20)*H$21) -> 87.379178 | M10: =I10+(I10/SUM(I$2:I$20)*I$21) -> 4.1331462
A11: 40 | B11: 66 | C11: 1 | E11: 67 | G11: 40 | H11: =B11 * (E11 / (B11 + C11)) -> 66 | I11: =C11 * (E11 / (B11 + C11)) -> 1 | K11: 40 | L11: =H11+(H11/SUM(H$2:H$20)*H$21) -> 67.058439 | M11: =I11+(I11/SUM(I$2:I$20)*I$21) -> 1.0332865
A12: 45 | B12: 50 | C12: 5 | E12: 55 | G12: 45 | H12: =B12 * (E12 / (B12 + C12)) -> 50 | I12: =C12 * (E12 / (B12 + C12)) -> 5 | K12: 45 | L12: =H12+(H12/SUM(H$2:H$20)*H$21) -> 50.801848 | M12: =I12+(I12/SUM(I$2:I$20)*I$21) -> 5.1664327
A13: 50 | B13: 43 | C13: 4 | E13: 47 | G13: 50 | H13: =B13 * (E13 / (B13 + C13)) -> 43 | I13: =C13 * (E13 / (B13 + C13)) -> 4 | K13: 50 | L13: =H13+(H13/SUM(H$2:H$20)*H$21) -> 43.689589 | M13: =I13+(I13/SUM(I$2:I$20)*I$21) -> 4.1331462
A14: 55 | B14: 29 | C14: 1 | E14: 30 | G14: 55 | H14: =B14 * (E14 / (B14 + C14)) -> 29 | I14: =C14 * (E14 / (B14 + C14)) -> 1 | K14: 55 | L14: =H14+(H14/SUM(H$2:H$20)*H$21) -> 29.465072 | M14: =I14+(I14/SUM(I$2:I$20)*I$21) -> 1.0332865
A15: 60 | B15: 27 | C15: 3 | E15: 30 | G15: 60 | H15: =B15 * (E15 / (B15 + C15)) -> 27 | I15: =C15 * (E15 / (B15 + C15)) -> 3 | K15: 60 | L15: =H15+(H15/SUM(H$2:H$20)*H$21) -> 27.432998 | M15: =I15+(I15/SUM(I$2:I$20)*I$21) -> 3.0998596
A16: 65 | B16: 12 | C16: 1 | E16: 13 | G16: 65 | H16: =B16 * (E16 / (B16 + C16)) -> 12 | I16: =C16 * (E16 / (B16 + C16)) -> 1 | K16: 65 | L16: =H16+(H16/SUM(H$2:H$20)*H$21) -> 12.192443 | M16: =I16+(I16/SUM(I$2:I$20)*I$21) -> 1.0332865
A17: 70 | B17: 8 | C17: 2 | E17: 10 | G17: 70 | H17: =B17 * (E17 / (B17 + C17)) -> 8 | I17: =C17 * (E17 / (B17 + C17)) -> 2 | K17: 70 | L17: =H17+(H17/SUM(H$2:H$20)*H$21) -> 8.1282957 | M17: =I17+(I17/SUM(I$2:I$20)*I$21) -> 2.0665731
A18: 75 | B18: 11 | C18: 2 | E18: 13 | G18: 75 | H18: =B18 * (E18 / (B18 + C18)) -> 11 | I18: =C18 * (E18 / (B18 + C18)) -> 2 | K18: 75 | L18: =H18+(H18/SUM(H$2:H$20)*H$21) -> 11.176407 | M18: =I18+(I18/SUM(I$2:I$20)*I$21) -> 2.0665731
A19: 80 | B19: 5 | E19: 5 | G19: 80 | H19: =B19 * (E19 / (B19 + C19)) -> 5 | I19: =C19 * (E19 / (B19 + C19)) -> 0 | K19: 80 | L19: =H19+(H19/SUM(H$2:H$20)*H$21) -> 5.0801848 | M19: =I19+(I19/SUM(I$2:I$20)*I$21) -> 0
A20: 85 | B20: 11 | C20: 2 | E20: 13 | G20: 85 | H20: =B20 * (E20 / (B20 + C20)) -> 11 | I20: =C20 * (E20 / (B20 + C20)) -> 2 | K20: 85 | L20: =H20+(H20/SUM(H$2:H$20)*H$21) -> 11.176407 | M20: =I20+(I20/SUM(I$2:I$20)*I$21) -> 2.0665731
A21: No especificado | B21: 11 | C21: 2 | E21: 13 | G21: No especificado | H21: =B21 * (E21 / (B21 + C21)) -> 11 | I21: =C21 * (E21 / (B21 + C21)) -> 2
A23: Hombres | B23: Mujeres | C23: Total | E23: Hombres | F23: Mujeres | G23: Total
A24: 2 | C24: 2 | E24: 0 | F24: =A24+(A24/SUM(A$24:A$42)*A$43) -> 2.0015361 | G24: =B24+(B24/SUM(B$24:B$42)*B$43) -> 0
A25: 4 | C25: 4 | E25: 1 | F25: =A25+(A25/SUM(A$24:A$42)*A$43) -> 4.0030722 | G25: =B25+(B25/SUM(B$24:B$42)*B$43) -> 0
A26: 1 | C26: 1 | E26: 5 | F26: =A26+(A26/SUM(A$24:A$42)*A$43) -> 1.000768 | G26: =B26+(B26/SUM(B$24:B$42)*B$43) -> 0
A27: 8 | B27: 4 | C27: 12 | E27: 10 | F27: =A27+(A27/SUM(A$24:A$42)*A$43) -> 8.0061444 | G27: =B27+(B27/SUM(B$24:B$42)*B$43) -> 4
A28: 70 | B28: 14 | C28: 84 | E28: 15 | F28: =A28+(A28/SUM(A$24:A$42)*A$43) -> 70.053763 | G28: =B28+(B28/SUM(B$24:B$42)*B$43) -> 14
A29: 189 | B29: 22 | C29: 211 | E29: 20 | F29: =A29+(A29/SUM(A$24:A$42)*A$43) -> 189.14516 | G29: =B29+(B29/SUM(B$24:B$42)*B$43) -> 22
A30: 220 | B30: 28 | C30: 248 | E30: 25 | F30: =A30+(A30/SUM(A$24:A$42)*A$43) -> 220.16897 | G30: =B30+(B30/SUM(B$24:B$42)*B$43) -> 28
A31: 194 | B31: 21 | C31: 215 | E31: 30 | F31: =A31+(A31/SUM(A$24:A$42)*A$43) -> 194.149 | G31: =B31+(B31/SUM(B$24:B$42)*B$43) -> 21
A32: 156 | B32: 16 | C32: 172 | E32: 35 | F32: =A32+(A32/SUM(A$24:A$42)*A$43) -> 156.11982 | G32: =B32+(B32/SUM(B$24:B$42)*B$43) -> 16
A33: 125 | B33: 23 | C33: 148 | E33: 40 | F33: =A33+(A33/SUM(A$24:A$42)*A$43) -> 125.09601 | G33: =B33+(B33/SUM(B$24:B$42)*B$43) -> 23
A34: 116 | B34: 8 | C34: 124 | E34: 45 | F34: =A34+(A34/SUM(A$24:A$42)*A$43) -> 116.08909 | G34: =B34+(B34/SUM(B$24:B$42)*B$43) -> 8
A35: 79 | B35: 7 | C35: 86 | E35: 50 | F35: =A35+(A35/SUM(A$24:A$42)*A$43) -> 79.060676 | G35: =B35+(B35/SUM(B$24:B$42)*B$43) -> 7
A36: 51 | B36: 7 | C36: 58 | E36: 55 | F36: =A36+(A36/SUM(A$24:A$42)*A$43) -> 51.039171 | G36: =B36+(B36/SUM(B$24:B$42)*B$43) -> 7
A37: 32 | B37: 4 | C37: 36 | E37: 60 | F37: =A37+(A37/SUM(A$24:A$42)*A$43) -> 32.024578 | G37: =B37+(B37/SUM(B$24:B$42)*B$43) -> 4
A38: 24 | B38: 6 | C38: 30 | E38: 65 | F38: =A38+(A38/SUM(A$24:A$42)*A$43) -> 24.018433 | G38: =B38+(B38/SUM(B$24:B$42)*B$43) -> 6
... A42: 3 | B42: 1 | C42: 4 | E42: 85 | F42: =A42+(A42/SUM(A$24:A$42)*A$43) -> 3.0023041 | G42: =B42+(B42/SUM(B$24:B$42)*B$43) -> 1
A43: 1 | C43: 1
F44: =SUM(F24:F42) -> 1303

Sheet Homicidios
A1: year | B1: year | C1: sex | D1: age | E1: deaths | G1: year | H1: sex | I1: age | J1: deaths
A2: 1990 | B2: 2019 | C2: male | D2: 0 | E2: 2.0015361 | G2: 2019 | H2: female | I2: 0 | J2: 0
A3: 1990 | B3: 2019 | C3: male | D3: 1 | E3: 4.0030722 | G3: 2019 | H3: female | I3: 1 | J3: 0
A4: 1990 | B4: 2019 | C4: male | D4: 5 | E4: 1.000768 | G4: 2019 | H4: female | I4: 5 | J4: 0
A5: 1990 | B5: 2019 | C5: male | D5: 10 | E5: 8.0061444 | G5: 2019 | H5: female | I5: 10 | J5: 4
A6: 1990 | B6: 2019 | C6: male | D6: 15 | E6: 70.053763 | G6: 2019 | H6: female | I6: 15 | J6: 14
A7: 1990 | B7: 2019 | C7: male | D7: 20 | E7: 189.14516 | G7: 2019 | H7: female | I7: 20 | J7: 22
A8: 1990 | B8: 2019 | C8: male | D8: 25 | E8: 220.16897 | G8: 2019 | H8: female | I8: 25 | J8: 28
A9: 1990 | B9: 2019 | C9: male | D9: 30 | E9: 194.149 | G9: 2019 | H9: female | I9: 30 | J9: 21
A10: 1990 | B10: 2019 | C10: male | D10: 35 | E10: 156.11982 | G10: 2019 | H10: female | I10: 35 | J10: 16
A11: 1990 | B11: 2019 | C11: male | D11: 40 | E11: 125.09601 | G11: 2019 | H11: female | I11: 40 | J11: 23
A12: 1990 | B12: 2019 | C12: male | D12: 45 | E12: 116.08909 | G12: 2019 | H12: female | I12: 45 | J12: 8
A13: 1990 | B13: 2019 | C13: male | D13: 50 | E13: 79.060676 | G13: 2019 | H13: female | I13: 50 | J13: 7
... A20: 1990 | B20: 2019 | C20: male | D20: 85 | E20: 3.0023041 | G20: 2019 | H20: female | I20: 85 | J20: 1

Sheet Defunciones generales
A1: Esta informacion, la obtenemos de nuestra base anteriormente onbtenida de defunciones generales de Veracruz
B2: Edad | C2: Hombres | D2: Mujeres | E2: year
B3: 0 | C3: 731 | D3: 643 | E3: 2019
B4: 1 | C4: 152 | D4: 135 | E4: 2019
B5: 5 | C5: 122 | D5: 84 | E5: 2019
B6: 10 | C6: 356 | D6: 144 | E6: 2019
B7: 15 | C7: 640 | D7: 175 | E7: 2019
B8: 20 | C8: 833 | D8: 239 | E8: 2019
B9: 25 | C9: 834 | D9: 311 | E9: 2019
B10: 30 | C10: 924 | D10: 374 | E10: 2019
B11: 35 | C11: 1077 | D11: 550 | E11: 2019
B12: 40 | C12: 1421 | D12: 870 | E12: 2019
B13: 45 | C13: 106 | D13: 86 | E13: 2019
B14: 50 | C14: 1810 | D14: 1114 | E14: 2019
... B21: 85 | C21: 4797 | D21: 6195 | E21: 2019

Sheet LT Ver
A1: x | B1: n | C1: mx | D1: ax | E1: qx | F1: px | G1: lx | H1: dx | I1: Lx | J1: Tx | K1: ex
A2: 0 | B2: 1 | C2: 0.013144409 | D2: 0.080279593 | E2: 0.012987402 | F2: 0.9870126 | G2: 100000 | H2: 1298.7402 | I2: 98805.522 | J2: 7262802 | K2: 72.62802
A3: 1 | B3: 4 | C3: 0.00060758441 | D3: 2 | E3: 0.002427388 | F3: 0.99757261 | G3: 98701.26 | H3: 239.58625 | I3: 394325.87 | J3: 7163996.5 | K3: 72.582625
A4: 5 | B4: 5 | C4: 0.00030749772 | D4: 2.5 | E4: 0.0015363076 | F4: 0.99846369 | G4: 98461.674 | H4: 151.26742 | I4: 491930.2 | J4: 6769670.6 | K4: 68.754373
A5: 10 | B5: 5 | C5: 0.00034837932 | D5: 2.5 | E5: 0.0017403808 | F5: 0.99825962 | G5: 98310.406 | H5: 171.09755 | I5: 491124.29 | J5: 6277740.4 | K5: 63.856317
A6: 15 | B6: 5 | C6: 0.0010253722 | D6: 2.5 | E6: 0.0051137523 | F6: 0.99488625 | G6: 98139.309 | H6: 501.86011 | I6: 489441.89 | J6: 5786616.1 | K6: 58.963286
A7: 20 | B7: 5 | C7: 0.0021781228 | D7: 2.5 | E7: 0.010831632 | F7: 0.98916837 | G7: 97637.449 | H7: 1057.573 | I7: 485543.31 | J7: 5297174.3 | K7: 54.25351
A8: 25 | B8: 5 | C8: 0.0030619934 | D8: 2.5 | E8: 0.01519366 | F8: 0.98480634 | G8: 96579.876 | H8: 1467.4018 | I8: 479230.87 | J8: 4811630.9 | K8: 49.820223
A9: 30 | B9: 5 | C9: 0.0031766225 | D9: 2.5 | E9: 0.01575797 | F9: 0.98424203 | G9: 95112.474 | H9: 1498.7795 | I9: 471815.42 | J9: 4332400.1 | K9: 45.550283
A10: 35 | B10: 5 | C10: 0.0035756577 | D10: 2.5 | E10: 0.017719888 | F10: 0.98228011 | G10: 93613.694 | H10: 1658.8241 | I10: 463921.41 | J10: 3860584.7 | K10: 41.239529
A11: 40 | B11: 5 | C11: 0.0043741725 | D11: 2.5 | E11: 0.021634282 | F11: 0.97836572 | G11: 91954.87 | H11: 1989.3776 | I11: 454800.91 | J11: 3396663.2 | K11: 36.938372
A12: 45 | B12: 5 | C12: 0.0059846194 | D12: 2.5 | E12: 0.029482001 | F12: 0.970518 | G12: 89965.493 | H12: 2652.3627 | I12: 443196.56 | J12: 2941862.3 | K12: 32.699897
A13: 50 | B13: 5 | C13: 0.0080997387 | D13: 2.5 | E13: 0.039694898 | F13: 0.9603051 | G13: 87313.13 | H13: 3465.8857 | I13: 427900.93 | J13: 2498665.8 | K13: 28.617297
... A19: 80 | B19: 5 | C19: 0.078816557 | D19: 2.5 | E19: 0.329214 | F19: 0.670786 | G19: 42945.465 | H19: 14138.248 | I19: 179381.7 | J19: 394808.28 | K19: 9.1932473
A20: 85 | C20: 0.13372174 | E20: 1 | F20: 0 | G20: 28807.217 | H20: 28807.217 | I20: 215426.57 | J20: 215426.57 | K20: 7.4782156
A24: x | B24: n | C24: mx | D24: ax | E24: qx | F24: px | G24: lx | H24: dx | I24: Lx | J24: Tx | K24: ex
A25: 0 | B25: 1 | C25: 0.011783679 | D25: 0.085994301 | E25: 0.011658117 | F25: 0.98834188 | G25: 100000 | H25: 1165.8117 | I25: 98934.441 | J25: 7839635 | K25: 78.39635
A26: 1 | B26: 4 | C26: 0.00055106764 | D26: 2 | E26: 0.0022018438 | F26: 0.99779816 | G26: 98834.188 | H26: 217.61745 | I26: 394901.52 | J26: 7740700.6 | K26: 78.320071
A27: 5 | B27: 5 | C27: 0.00025663751 | D27: 2.5 | E27: 0.0012823648 | F27: 0.99871764 | G27: 98616.571 | H27: 126.46242 | I27: 492766.7 | J27: 7345799.1 | K27: 74.488486
A28: 10 | B28: 5 | C28: 0.00024698909 | D28: 2.5 | E28: 0.0012341834 | F28: 0.99876582 | G28: 98490.108 | H28: 121.55485 | I28: 492146.66 | J28: 6853032.4 | K28: 69.58092
A29: 15 | B29: 5 | C29: 0.00042275602 | D29: 2.5 | E29: 0.0021115484 | F29: 0.99788845 | G29: 98368.554 | H29: 207.70996 | I29: 491323.49 | J29: 6360885.7 | K29: 64.663813
A30: 20 | B30: 5 | C30: 0.00056401034 | D30: 2.5 | E30: 0.0028160809 | F30: 0.99718392 | G30: 98160.844 | H30: 276.42888 | I30: 490113.15 | J30: 5869562.2 | K30: 59.795352
A31: 25 | B31: 5 | C31: 0.000777347 | D31: 2.5 | E31: 0.0038791963 | F31: 0.9961208 | G31: 97884.415 | H31: 379.71286 | I31: 488472.79 | J31: 5379449.1 | K31: 54.957156
A32: 30 | B32: 5 | C32: 0.001022347 | D32: 2.5 | E32: 0.0050987034 | F32: 0.9949013 | G32: 97504.702 | H32: 497.14755 | I32: 486280.64 | J32: 4890976.3 | K32: 50.16144
A33: 35 | B33: 5 | C33: 0.0012469743 | D33: 2.5 | E33: 0.0062154949 | F33: 0.99378451 | G33: 97007.554 | H33: 602.94996 | I33: 483530.4 | J33: 4404695.7 | K33: 45.405697
A34: 40 | B34: 5 | C34: 0.0019078806 | D34: 2.5 | E34: 0.0094941188 | F34: 0.99050588 | G34: 96404.604 | H34: 915.27677 | I34: 479734.83 | J34: 3921165.3 | K34: 40.674045
A35: 45 | B35: 5 | C35: 0.0031969779 | D35: 2.5 | E35: 0.015858144 | F35: 0.98414186 | G35: 95489.328 | H35: 1514.2835 | I35: 473660.93 | J35: 3441430.4 | K35: 36.039948
A36: 50 | B36: 5 | C36: 0.004359993 | D36: 2.5 | E36: 0.021564908 | F36: 0.97843509 | G36: 93975.044 | H36: 2026.5631 | I36: 464808.81 | J36: 2967769.5 | K36: 31.5804
... A42: 80 | B42: 5 | C42: 0.06650611 | D42: 2.5 | E42: 0.28512428 | F42: 0.71487572 | G42: 55675.139 | H42: 15874.334 | I42: 238689.86 | J42: 549104.01 | K42: 9.8626429
A43: 85 | C43: 0.1282184 | E43: 1 | F43: 0 | G43: 39800.805 | H43: 39800.805 | I43: 310414.15 | J43: 310414.15 | K43: 7.7991929
